Workbook

Sheet pokemon
A1: pokedex_id | B1: name | C1: hp | D1: attack | E1: defense | F1: special_attack | G1: special_defense | H1: speed | I1: remarks | J1: type1 | K1: type2 | L1: gen | M1: image1 | N1: image2 | O1: impl_flg | P1: pokedex_id | Q1: name | R1: hp | S1: attack | T1: defense | U1: special_attack | V1: special_defense | W1: speed | X1: remarks | Y1: type1 | Z1: type2 | AA1: gen | AB1: image1 | AC1: image2 | AD1: impl_flg | AE1: ="INSERT INTO pokedex ("&_xlfn.TEXTJOIN(", ",FALSE,$A$1:$O$1)&") VALUES" -> INSERT INTO pokedex (pokedex_id, name, hp, attack, defense, special_attack, special_defense, speed, remarks, type1, type2, gen, image1, image2, impl_flg) VALUES
A2: bpchar | B2: varchar | C2: number | D2: number | E2: number | F2: number | G2: number | H2: number | I2: varchar | J2: varchar | K2: varchar | L2: varchar | M2: varchar | N2: varchar | O2: boolean | P2: 作業用
A3: bpchar | B3: varchar(20) not null | C3: integer not null | D3: integer not null | E3: integer not null | F3: integer not null | G3: integer not null | H3: integer not null | I3: varchar(256) not null | J3: varchar(10) not null | K3: varchar(10) | L3: varchar(16) not null | M3: varchar(256) | N3: varchar(256) | O3: boolean not null | AB3: =SEARCH("NOT NULL",UPPER(E$3)) -> 9
A4: 0001N01 | B4: フシギダネ | C4: 45 | D4: 49 | E4: 49 | F4: 65 | G4: 65 | H4: 45 | J4: grass | K4: poison | L4: g1 | O4: TRUE | P4: =IF(A4="",IF(ISNUMBER(SEARCH("NOT NULL",UPPER(A$3))),"''","null"),SUBSTITUTE(VLOOKUP(A$2,convert!$A$1:$B$4,2,0),"@@@",A4)) -> '0001N01' | Q4: =IF(B4="",IF(ISNUMBER(SEARCH("NOT NULL",UPPER(B$3))),"''","null"),SUBSTITUTE(VLOOKUP(B$2,convert!$A$1:$B$4,2,0),"@@@",B4)) -> 'フシギダネ' | R4: =IF(C4="",IF(ISNUMBER(SEARCH("NOT NULL",UPPER(C$3))),"''","null"),SUBSTITUTE(VLOOKUP(C$2,convert!$A$1:$B$4,2,0),"@@@",C4)) -> 45 | S4: =IF(D4="",IF(ISNUMBER(SEARCH("NOT NULL",UPPER(D$3))),"''","null"),SUBSTITUTE(VLOOKUP(D$2,convert!$A$1:$B$4,2,0),"@@@",D4)) -> 49 | T4: =IF(E4="",IF(ISNUMBER(SEARCH("NOT NULL",UPPER(E$3))),"''","null"),SUBSTITUTE(VLOOKUP(E$2,convert!$A$1:$B$4,2,0),"@@@",E4)) -> 49 | U4: =IF(F4="",IF(ISNUMBER(SEARCH("NOT NULL",UPPER(F$3))),"''","null"),SUBSTITUTE(VLOOKUP(F$2,convert!$A$1:$B$4,2,0),"@@@",F4)) -> 65 | V4: =IF(G4="",IF(ISNUMBER(SEARCH("NOT NULL",UPPER(G$3))),"''","null"),SUBSTITUTE(VLOOKUP(G$2,convert!$A$1:$B$4,2,0),"@@@",G4)) -> 65 | W4: =IF(H4="",IF(ISNUMBER(SEARCH("NOT NULL",UPPER(H$3))),"''","null"),SUBSTITUTE(VLOOKUP(H$2,convert!$A$1:$B$4,2,0),"@@@",H4)) -> 45 | ... AD4: =IF(O4="",IF(ISNUMBER(SEARCH("NOT NULL",UPPER(O$3))),"''","null"),SUBSTITUTE(VLOOKUP(O$2,convert!$A$1:$B$4,2,0),"@@@",O4)) -> TRUE | AE4: =" ("&_xlfn.TEXTJOIN(", ",FALSE,P4:AD4)&")," -> ('0001N01', 'フシギダネ', 45, 49, 49, 65, 65, 45, '', 'grass', 'poison', 'g1', null, null, TRUE),
A5: 0002N01 | B5: フシギソウ | C5: 60 | D5: 62 | E5: 63 | F5: 80 | G5: 80 | H5: 60 | J5: grass | K5: poison | L5: g1 | O5: TRUE | P5: =IF(A5="",IF(ISNUMBER(SEARCH("NOT NULL",UPPER(A$3))),"''","null"),SUBSTITUTE(VLOOKUP(A$2,convert!$A$1:$B$4,2,0),"@@@",A5)) -> '0002N01' | Q5: =IF(B5="",IF(ISNUMBER(SEARCH("NOT NULL",UPPER(B$3))),"''","null"),SUBSTITUTE(VLOOKUP(B$2,convert!$A$1:$B$4,2,0),"@@@",B5)) -> 'フシギソウ' | R5: =IF(C5="",IF(ISNUMBER(SEARCH("NOT NULL",UPPER(C$3))),"''","null"),SUBSTITUTE(VLOOKUP(C$2,convert!$A$1:$B$4,2,0),"@@@",C5)) -> 60 | S5: =IF(D5="",IF(ISNUMBER(SEARCH("NOT NULL",UPPER(D$3))),"''","null"),SUBSTITUTE(VLOOKUP(D$2,convert!$A$1:$B$4,2,0),"@@@",D5)) -> 62 | T5: =IF(E5="",IF(ISNUMBER(SEARCH("NOT NULL",UPPER(E$3))),"''","null"),SUBSTITUTE(VLOOKUP(E$2,convert!$A$1:$B$4,2,0),"@@@",E5)) -> 63 | U5: =IF(F5="",IF(ISNUMBER(SEARCH("NOT NULL",UPPER(F$3))),"''","null"),SUBSTITUTE(VLOOKUP(F$2,convert!$A$1:$B$4,2,0),"@@@",F5)) -> 80 | V5: =IF(G5="",IF(ISNUMBER(SEARCH("NOT NULL",UPPER(G$3))),"''","null"),SUBSTITUTE(VLOOKUP(G$2,convert!$A$1:$B$4,2,0),"@@@",G5)) -> 80 | W5: =IF(H5="",IF(ISNUMBER(SEARCH("NOT NULL",UPPER(H$3))),"''","null"),SUBSTITUTE(VLOOKUP(H$2,convert!$A$1:$B$4,2,0),"@@@",H5)) -> 60 | ... AD5: =IF(O5="",IF(ISNUMBER(SEARCH("NOT NULL",UPPER(O$3))),"''","null"),SUBSTITUTE(VLOOKUP(O$2,convert!$A$1:$B$4,2,0),"@@@",O5)) -> TRUE | AE5: =" ("&_xlfn.TEXTJOIN(", ",FALSE,P5:AD5)&")," -> ('0002N01', 'フシギソウ', 60, 62, 63, 80, 80, 60, '', 'grass', 'poison', 'g1', null, null, TRUE),
A6: 0003N01 | B6: フシギバナ | C6: 80 | D6: 82 | E6: 83 | F6: 100 | G6: 100 | H6: 80 | J6: grass | K6: poison | L6: g1 | O6: TRUE | P6: =IF(A6="",IF(ISNUMBER(SEARCH("NOT NULL",UPPER(A$3))),"''","null"),SUBSTITUTE(VLOOKUP(A$2,convert!$A$1:$B$4,2,0),"@@@",A6)) -> '0003N01' | Q6: =IF(B6="",IF(ISNUMBER(SEARCH("NOT NULL",UPPER(B$3))),"''","null"),SUBSTITUTE(VLOOKUP(B$2,convert!$A$1:$B$4,2,0),"@@@",B6)) -> 'フシギバナ' | R6: =IF(C6="",IF(ISNUMBER(SEARCH("NOT NULL",UPPER(C$3))),"''","null"),SUBSTITUTE(VLOOKUP(C$2,convert!$A$1:$B$4,2,0),"@@@",C6)) -> 80 | S6: =IF(D6="",IF(ISNUMBER(SEARCH("NOT NULL",UPPER(D$3))),"''","null"),SUBSTITUTE(VLOOKUP(D$2,convert!$A$1:$B$4,2,0),"@@@",D6)) -> 82 | T6: =IF(E6="",IF(ISNUMBER(SEARCH("NOT NULL",UPPER(E$3))),"''","null"),SUBSTITUTE(VLOOKUP(E$2,convert!$A$1:$B$4,2,0),"@@@",E6)) -> 83 | U6: =IF(F6="",IF(ISNUMBER(SEARCH("NOT NULL",UPPER(F$3))),"''","null"),SUBSTITUTE(VLOOKUP(F$2,convert!$A$1:$B$4,2,0),"@@@",F6)) -> 100 | V6: =IF(G6="",IF(ISNUMBER(SEARCH("NOT NULL",UPPER(G$3))),"''","null"),SUBSTITUTE(VLOOKUP(G$2,convert!$A$1:$B$4,2,0),"@@@",G6)) -> 100 | W6: =IF(H6="",IF(ISNUMBER(SEARCH("NOT NULL",UPPER(H$3))),"''","null"),SUBSTITUTE(VLOOKUP(H$2,convert!$A$1:$B$4,2,0),"@@@",H6)) -> 80 | ... AD6: =IF(O6="",IF(ISNUMBER(SEARCH("NOT NULL",UPPER(O$3))),"''","null"),SUBSTITUTE(VLOOKUP(O$2,convert!$A$1:$B$4,2,0),"@@@",O6)) -> TRUE | AE6: =" ("&_xlfn.TEXTJOIN(", ",FALSE,P6:AD6)&")," -> ('0003N01', 'フシギバナ', 80, 82, 83, 100, 100, 80, '', 'grass', 'poison', 'g1', null, null, TRUE),
A7: 0003M01 | B7: メガフシギバナ | C7: 80 | D7: 100 | E7: 123 | F7: 122 | G7: 120 | H7: 80 | J7: grass | K7: poison | L7: g6 | O7: TRUE | P7: =IF(A7="",IF(ISNUMBER(SEARCH("NOT NULL",UPPER(A$3))),"''","null"),SUBSTITUTE(VLOOKUP(A$2,convert!$A$1:$B$4,2,0),"@@@",A7)) -> '0003M01' | Q7: =IF(B7="",IF(ISNUMBER(SEARCH("NOT NULL",UPPER(B$3))),"''","null"),SUBSTITUTE(VLOOKUP(B$2,convert!$A$1:$B$4,2,0),"@@@",B7)) -> 'メガフシギバナ' | R7: =IF(C7="",IF(ISNUMBER(SEARCH("NOT NULL",UPPER(C$3))),"''","null"),SUBSTITUTE(VLOOKUP(C$2,convert!$A$1:$B$4,2,0),"@@@",C7)) -> 80 | S7: =IF(D7="",IF(ISNUMBER(SEARCH("NOT NULL",UPPER(D$3))),"''","null"),SUBSTITUTE(VLOOKUP(D$2,convert!$A$1:$B$4,2,0),"@@@",D7)) -> 100 | T7: =IF(E7="",IF(ISNUMBER(SEARCH("NOT NULL",UPPER(E$3))),"''","null"),SUBSTITUTE(VLOOKUP(E$2,convert!$A$1:$B$4,2,0),"@@@",E7)) -> 123 | U7: =IF(F7="",IF(ISNUMBER(SEARCH("NOT NULL",UPPER(F$3))),"''","null"),SUBSTITUTE(VLOOKUP(F$2,convert!$A$1:$B$4,2,0),"@@@",F7)) -> 122 | V7: =IF(G7="",IF(ISNUMBER(SEARCH("NOT NULL",UPPER(G$3))),"''","null"),SUBSTITUTE(VLOOKUP(G$2,convert!$A$1:$B$4,2,0),"@@@",G7)) -> 120 | W7: =IF(H7="",IF(ISNUMBER(SEARCH("NOT NULL",UPPER(H$3))),"''","null"),SUBSTITUTE(VLOOKUP(H$2,convert!$A$1:$B$4,2,0),"@@@",H7)) -> 80 | ... AD7: =IF(O7="",IF(ISNUMBER(SEARCH("NOT NULL",UPPER(O$3))),"''","null"),SUBSTITUTE(VLOOKUP(O$2,convert!$A$1:$B$4,2,0),"@@@",O7)) -> TRUE | AE7: =" ("&_xlfn.TEXTJOIN(", ",FALSE,P7:AD7)&")," -> ('0003M01', 'メガフシギバナ', 80, 100, 123, 122, 120, 80, '', 'grass', 'poison', 'g6', null, null, TRUE),
A8: 0004N01 | B8: ヒトカゲ | C8: 39 | D8: 52 | E8: 43 | F8: 60 | G8: 50 | H8: 65 | J8: fire | L8: g1 | O8: TRUE | P8: =IF(A8="",IF(ISNUMBER(SEARCH("NOT NULL",UPPER(A$3))),"''","null"),SUBSTITUTE(VLOOKUP(A$2,convert!$A$1:$B$4,2,0),"@@@",A8)) -> '0004N01' | Q8: =IF(B8="",IF(ISNUMBER(SEARCH("NOT NULL",UPPER(B$3))),"''","null"),SUBSTITUTE(VLOOKUP(B$2,convert!$A$1:$B$4,2,0),"@@@",B8)) -> 'ヒトカゲ' | R8: =IF(C8="",IF(ISNUMBER(SEARCH("NOT NULL",UPPER(C$3))),"''","null"),SUBSTITUTE(VLOOKUP(C$2,convert!$A$1:$B$4,2,0),"@@@",C8)) -> 39 | S8: =IF(D8="",IF(ISNUMBER(SEARCH("NOT NULL",UPPER(D$3))),"''","null"),SUBSTITUTE(VLOOKUP(D$2,convert!$A$1:$B$4,2,0),"@@@",D8)) -> 52 | T8: =IF(E8="",IF(ISNUMBER(SEARCH("NOT NULL",UPPER(E$3))),"''","null"),SUBSTITUTE(VLOOKUP(E$2,convert!$A$1:$B$4,2,0),"@@@",E8)) -> 43 | U8: =IF(F8="",IF(ISNUMBER(SEARCH("NOT NULL",UPPER(F$3))),"''","null"),SUBSTITUTE(VLOOKUP(F$2,convert!$A$1:$B$4,2,0),"@@@",F8)) -> 60 | V8: =IF(G8="",IF(ISNUMBER(SEARCH("NOT NULL",UPPER(G$3))),"''","null"),SUBSTITUTE(VLOOKUP(G$2,convert!$A$1:$B$4,2,0),"@@@",G8)) -> 50 | W8: =IF(H8="",IF(ISNUMBER(SEARCH("NOT NULL",UPPER(H$3))),"''","null"),SUBSTITUTE(VLOOKUP(H$2,convert!$A$1:$B$4,2,0),"@@@",H8)) -> 65 | ... AD8: =IF(O8="",IF(ISNUMBER(SEARCH("NOT NULL",UPPER(O$3))),"''","null"),SUBSTITUTE(VLOOKUP(O$2,convert!$A$1:$B$4,2,0),"@@@",O8)) -> TRUE | AE8: =" ("&_xlfn.TEXTJOIN(", ",FALSE,P8:AD8)&")," -> ('0004N01', 'ヒトカゲ', 39, 52, 43, 60, 50, 65, '', 'fire', null, 'g1', null, null, TRUE),
A9: 0005N01 | B9: リザード | C9: 58 | D9: 64 | E9: 58 | F9: 80 | G9: 65 | H9: 80 | J9: fire | L9: g1 | O9: TRUE | P9: =IF(A9="",IF(ISNUMBER(SEARCH("NOT NULL",UPPER(A$3))),"''","null"),SUBSTITUTE(VLOOKUP(A$2,convert!$A$1:$B$4,2,0),"@@@",A9)) -> '0005N01' | Q9: =IF(B9="",IF(ISNUMBER(SEARCH("NOT NULL",UPPER(B$3))),"''","null"),SUBSTITUTE(VLOOKUP(B$2,convert!$A$1:$B$4,2,0),"@@@",B9)) -> 'リザード' | R9: =IF(C9="",IF(ISNUMBER(SEARCH("NOT NULL",UPPER(C$3))),"''","null"),SUBSTITUTE(VLOOKUP(C$2,convert!$A$1:$B$4,2,0),"@@@",C9)) -> 58 | S9: =IF(D9="",IF(ISNUMBER(SEARCH("NOT NULL",UPPER(D$3))),"''","null"),SUBSTITUTE(VLOOKUP(D$2,convert!$A$1:$B$4,2,0),"@@@",D9)) -> 64 | T9: =IF(E9="",IF(ISNUMBER(SEARCH("NOT NULL",UPPER(E$3))),"''","null"),SUBSTITUTE(VLOOKUP(E$2,convert!$A$1:$B$4,2,0),"@@@",E9)) -> 58 | U9: =IF(F9="",IF(ISNUMBER(SEARCH("NOT NULL",UPPER(F$3))),"''","null"),SUBSTITUTE(VLOOKUP(F$2,convert!$A$1:$B$4,2,0),"@@@",F9)) -> 80 | V9: =IF(G9="",IF(ISNUMBER(SEARCH("NOT NULL",UPPER(G$3))),"''","null"),SUBSTITUTE(VLOOKUP(G$2,convert!$A$1:$B$4,2,0),"@@@",G9)) -> 65 | W9: =IF(H9="",IF(ISNUMBER(SEARCH("NOT NULL",UPPER(H$3))),"''","null"),SUBSTITUTE(VLOOKUP(H$2,convert!$A$1:$B$4,2,0),"@@@",H9)) -> 80 | ... AD9: =IF(O9="",IF(ISNUMBER(SEARCH("NOT NULL",UPPER(O$3))),"''","null"),SUBSTITUTE(VLOOKUP(O$2,convert!$A$1:$B$4,2,0),"@@@",O9)) -> TRUE | AE9: =" ("&_xlfn.TEXTJOIN(", ",FALSE,P9:AD9)&")," -> ('0005N01', 'リザード', 58, 64, 58, 80, 65, 80, '', 'fire', null, 'g1', null, null, TRUE),
A10: 0006N01 | B10: リザードン | C10: 78 | D10: 84 | E10: 78 | F10: 109 | G10: 85 | H10: 100 | J10: fire | K10: flying | L10: g1 | O10: TRUE | P10: =IF(A10="",IF(ISNUMBER(SEARCH("NOT NULL",UPPER(A$3))),"''","null"),SUBSTITUTE(VLOOKUP(A$2,convert!$A$1:$B$4,2,0),"@@@",A10)) -> '0006N01' | Q10: =IF(B10="",IF(ISNUMBER(SEARCH("NOT NULL",UPPER(B$3))),"''","null"),SUBSTITUTE(VLOOKUP(B$2,convert!$A$1:$B$4,2,0),"@@@",B10)) -> 'リザードン' | R10: =IF(C10="",IF(ISNUMBER(SEARCH("NOT NULL",UPPER(C$3))),"''","null"),SUBSTITUTE(VLOOKUP(C$2,convert!$A$1:$B$4,2,0),"@@@",C10)) -> 78 | S10: =IF(D10="",IF(ISNUMBER(SEARCH("NOT NULL",UPPER(D$3))),"''","null"),SUBSTITUTE(VLOOKUP(D$2,convert!$A$1:$B$4,2,0),"@@@",D10)) -> 84 | T10: =IF(E10="",IF(ISNUMBER(SEARCH("NOT NULL",UPPER(E$3))),"''","null"),SUBSTITUTE(VLOOKUP(E$2,convert!$A$1:$B$4,2,0),"@@@",E10)) -> 78 | U10: =IF(F10="",IF(ISNUMBER(SEARCH("NOT NULL",UPPER(F$3))),"''","null"),SUBSTITUTE(VLOOKUP(F$2,convert!$A$1:$B$4,2,0),"@@@",F10)) -> 109 | V10: =IF(G10="",IF(ISNUMBER(SEARCH("NOT NULL",UPPER(G$3))),"''","null"),SUBSTITUTE(VLOOKUP(G$2,convert!$A$1:$B$4,2,0),"@@@",G10)) -> 85 | W10: =IF(H10="",IF(ISNUMBER(SEARCH("NOT NULL",UPPER(H$3))),"''","null"),SUBSTITUTE(VLOOKUP(H$2,convert!$A$1:$B$4,2,0),"@@@",H10)) -> 100 | ... AD10: =IF(O10="",IF(ISNUMBER(SEARCH("NOT NULL",UPPER(O$3))),"''","null"),SUBSTITUTE(VLOOKUP(O$2,convert!$A$1:$B$4,2,0),"@@@",O10)) -> TRUE | AE10: =" ("&_xlfn.TEXTJOIN(", ",FALSE,P10:AD10)&")," -> ('0006N01', 'リザードン', 78, 84, 78, 109, 85, 100, '', 'fire', 'flying', 'g1', null, null, TRUE),
A11: 0006M01 | B11: メガリザードンX | C11: 78 | D11: 130 | E11: 111 | F11: 130 | G11: 85 | H11: 100 | J11: fire | K11: dragon | L11: g6 | O11: TRUE | P11: =IF(A11="",IF(ISNUMBER(SEARCH("NOT NULL",UPPER(A$3))),"''","null"),SUBSTITUTE(VLOOKUP(A$2,convert!$A$1:$B$4,2,0),"@@@",A11)) -> '0006M01' | Q11: =IF(B11="",IF(ISNUMBER(SEARCH("NOT NULL",UPPER(B$3))),"''","null"),SUBSTITUTE(VLOOKUP(B$2,convert!$A$1:$B$4,2,0),"@@@",B11)) -> 'メガリザードンX' | R11: =IF(C11="",IF(ISNUMBER(SEARCH("NOT NULL",UPPER(C$3))),"''","null"),SUBSTITUTE(VLOOKUP(C$2,convert!$A$1:$B$4,2,0),"@@@",C11)) -> 78 | S11: =IF(D11="",IF(ISNUMBER(SEARCH("NOT NULL",UPPER(D$3))),"''","null"),SUBSTITUTE(VLOOKUP(D$2,convert!$A$1:$B$4,2,0),"@@@",D11)) -> 130 | T11: =IF(E11="",IF(ISNUMBER(SEARCH("NOT NULL",UPPER(E$3))),"''","null"),SUBSTITUTE(VLOOKUP(E$2,convert!$A$1:$B$4,2,0),"@@@",E11)) -> 111 | U11: =IF(F11="",IF(ISNUMBER(SEARCH("NOT NULL",UPPER(F$3))),"''","null"),SUBSTITUTE(VLOOKUP(F$2,convert!$A$1:$B$4,2,0),"@@@",F11)) -> 130 | V11: =IF(G11="",IF(ISNUMBER(SEARCH("NOT NULL",UPPER(G$3))),"''","null"),SUBSTITUTE(VLOOKUP(G$2,convert!$A$1:$B$4,2,0),"@@@",G11)) -> 85 | W11: =IF(H11="",IF(ISNUMBER(SEARCH("NOT NULL",UPPER(H$3))),"''","null"),SUBSTITUTE(VLOOKUP(H$2,convert!$A$1:$B$4,2,0),"@@@",H11)) -> 100 | ... AD11: =IF(O11="",IF(ISNUMBER(SEARCH("NOT NULL",UPPER(O$3))),"''","null"),SUBSTITUTE(VLOOKUP(O$2,convert!$A$1:$B$4,2,0),"@@@",O11)) -> TRUE | AE11: =" ("&_xlfn.TEXTJOIN(", ",FALSE,P11:AD11)&")," -> ('0006M01', 'メガリザードンX', 78, 130, 111, 130, 85, 100, '', 'fire', 'dragon', 'g6', null, null, TRUE),
A12: 0006M02 | B12: メガリザードンY | C12: 78 | D12: 104 | E12: 78 | F12: 159 | G12: 115 | H12: 100 | J12: fire | K12: flying | L12: g6 | O12: TRUE | P12: =IF(A12="",IF(ISNUMBER(SEARCH("NOT NULL",UPPER(A$3))),"''","null"),SUBSTITUTE(VLOOKUP(A$2,convert!$A$1:$B$4,2,0),"@@@",A12)) -> '0006M02' | Q12: =IF(B12="",IF(ISNUMBER(SEARCH("NOT NULL",UPPER(B$3))),"''","null"),SUBSTITUTE(VLOOKUP(B$2,convert!$A$1:$B$4,2,0),"@@@",B12)) -> 'メガリザードンY' | R12: =IF(C12="",IF(ISNUMBER(SEARCH("NOT NULL",UPPER(C$3))),"''","null"),SUBSTITUTE(VLOOKUP(C$2,convert!$A$1:$B$4,2,0),"@@@",C12)) -> 78 | S12: =IF(D12="",IF(ISNUMBER(SEARCH("NOT NULL",UPPER(D$3))),"''","null"),SUBSTITUTE(VLOOKUP(D$2,convert!$A$1:$B$4,2,0),"@@@",D12)) -> 104 | T12: =IF(E12="",IF(ISNUMBER(SEARCH("NOT NULL",UPPER(E$3))),"''","null"),SUBSTITUTE(VLOOKUP(E$2,convert!$A$1:$B$4,2,0),"@@@",E12)) -> 78 | U12: =IF(F12="",IF(ISNUMBER(SEARCH("NOT NULL",UPPER(F$3))),"''","null"),SUBSTITUTE(VLOOKUP(F$2,convert!$A$1:$B$4,2,0),"@@@",F12)) -> 159 | V12: =IF(G12="",IF(ISNUMBER(SEARCH("NOT NULL",UPPER(G$3))),"''","null"),SUBSTITUTE(VLOOKUP(G$2,convert!$A$1:$B$4,2,0),"@@@",G12)) -> 115 | W12: =IF(H12="",IF(ISNUMBER(SEARCH("NOT NULL",UPPER(H$3))),"''","null"),SUBSTITUTE(VLOOKUP(H$2,convert!$A$1:$B$4,2,0),"@@@",H12)) -> 100 | ... AD12: =IF(O12="",IF(ISNUMBER(SEARCH("NOT NULL",UPPER(O$3))),"''","null"),SUBSTITUTE(VLOOKUP(O$2,convert!$A$1:$B$4,2,0),"@@@",O12)) -> TRUE | AE12: =" ("&_xlfn.TEXTJOIN(", ",FALSE,P12:AD12)&")," -> ('0006M02', 'メガリザードンY', 78, 104, 78, 159, 115, 100, '', 'fire', 'flying', 'g6', null, null, TRUE),
A13: 0007N01 | B13: ゼニガメ | C13: 44 | D13: 48 | E13: 65 | F13: 50 | G13: 64 | H13: 43 | J13: water | L13: g1 | O13: TRUE | P13: =IF(A13="",IF(ISNUMBER(SEARCH("NOT NULL",UPPER(A$3))),"''","null"),SUBSTITUTE(VLOOKUP(A$2,convert!$A$1:$B$4,2,0),"@@@",A13)) -> '0007N01' | Q13: =IF(B13="",IF(ISNUMBER(SEARCH("NOT NULL",UPPER(B$3))),"''","null"),SUBSTITUTE(VLOOKUP(B$2,convert!$A$1:$B$4,2,0),"@@@",B13)) -> 'ゼニガメ' | R13: =IF(C13="",IF(ISNUMBER(SEARCH("NOT NULL",UPPER(C$3))),"''","null"),SUBSTITUTE(VLOOKUP(C$2,convert!$A$1:$B$4,2,0),"@@@",C13)) -> 44 | S13: =IF(D13="",IF(ISNUMBER(SEARCH("NOT NULL",UPPER(D$3))),"''","null"),SUBSTITUTE(VLOOKUP(D$2,convert!$A$1:$B$4,2,0),"@@@",D13)) -> 48 | T13: =IF(E13="",IF(ISNUMBER(SEARCH("NOT NULL",UPPER(E$3))),"''","null"),SUBSTITUTE(VLOOKUP(E$2,convert!$A$1:$B$4,2,0),"@@@",E13)) -> 65 | U13: =IF(F13="",IF(ISNUMBER(SEARCH("NOT NULL",UPPER(F$3))),"''","null"),SUBSTITUTE(VLOOKUP(F$2,convert!$A$1:$B$4,2,0),"@@@",F13)) -> 50 | V13: =IF(G13="",IF(ISNUMBER(SEARCH("NOT NULL",UPPER(G$3))),"''","null"),SUBSTITUTE(VLOOKUP(G$2,convert!$A$1:$B$4,2,0),"@@@",G13)) -> 64 | W13: =IF(H13="",IF(ISNUMBER(SEARCH("NOT NULL",UPPER(H$3))),"''","null"),SUBSTITUTE(VLOOKUP(H$2,convert!$A$1:$B$4,2,0),"@@@",H13)) -> 43 | ... AD13: =IF(O13="",IF(ISNUMBER(SEARCH("NOT NULL",UPPER(O$3))),"''","null"),SUBSTITUTE(VLOOKUP(O$2,convert!$A$1:$B$4,2,0),"@@@",O13)) -> TRUE | AE13: =" ("&_xlfn.TEXTJOIN(", ",FALSE,P13:AD13)&")," -> ('0007N01', 'ゼニガメ', 44, 48, 65, 50, 64, 43, '', 'water', null, 'g1', null, null, TRUE),
A14: 0008N01 | B14: カメール | C14: 59 | D14: 63 | E14: 80 | F14: 65 | G14: 80 | H14: 58 | J14: water | L14: g1 | O14: TRUE | P14: =IF(A14="",IF(ISNUMBER(SEARCH("NOT NULL",UPPER(A$3))),"''","null"),SUBSTITUTE(VLOOKUP(A$2,convert!$A$1:$B$4,2,0),"@@@",A14)) -> '0008N01' | Q14: =IF(B14="",IF(ISNUMBER(SEARCH("NOT NULL",UPPER(B$3))),"''","null"),SUBSTITUTE(VLOOKUP(B$2,convert!$A$1:$B$4,2,0),"@@@",B14)) -> 'カメール' | R14: =IF(C14="",IF(ISNUMBER(SEARCH("NOT NULL",UPPER(C$3))),"''","null"),SUBSTITUTE(VLOOKUP(C$2,convert!$A$1:$B$4,2,0),"@@@",C14)) -> 59 | S14: =IF(D14="",IF(ISNUMBER(SEARCH("NOT NULL",UPPER(D$3))),"''","null"),SUBSTITUTE(VLOOKUP(D$2,convert!$A$1:$B$4,2,0),"@@@",D14)) -> 63 | T14: =IF(E14="",IF(ISNUMBER(SEARCH("NOT NULL",UPPER(E$3))),"''","null"),SUBSTITUTE(VLOOKUP(E$2,convert!$A$1:$B$4,2,0),"@@@",E14)) -> 80 | U14: =IF(F14="",IF(ISNUMBER(SEARCH("NOT NULL",UPPER(F$3))),"''","null"),SUBSTITUTE(VLOOKUP(F$2,convert!$A$1:$B$4,2,0),"@@@",F14)) -> 65 | V14: =IF(G14="",IF(ISNUMBER(SEARCH("NOT NULL",UPPER(G$3))),"''","null"),SUBSTITUTE(VLOOKUP(G$2,convert!$A$1:$B$4,2,0),"@@@",G14)) -> 80 | W14: =IF(H14="",IF(ISNUMBER(SEARCH("NOT NULL",UPPER(H$3))),"''","null"),SUBSTITUTE(VLOOKUP(H$2,convert!$A$1:$B$4,2,0),"@@@",H14)) -> 58 | ... AD14: =IF(O14="",IF(ISNUMBER(SEARCH("NOT NULL",UPPER(O$3))),"''","null"),SUBSTITUTE(VLOOKUP(O$2,convert!$A$1:$B$4,2,0),"@@@",O14)) -> TRUE | AE14: =" ("&_xlfn.TEXTJOIN(", ",FALSE,P14:AD14)&")," -> ('0008N01', 'カメール', 59, 63, 80, 65, 80, 58, '', 'water', null, 'g1', null, null, TRUE),
A15: 0009N01 | B15: カメックス | C15: 79 | D15: 83 | E15: 100 | F15: 85 | G15: 105 | H15: 78 | J15: water | L15: g1 | O15: TRUE | P15: =IF(A15="",IF(ISNUMBER(SEARCH("NOT NULL",UPPER(A$3))),"''","null"),SUBSTITUTE(VLOOKUP(A$2,convert!$A$1:$B$4,2,0),"@@@",A15)) -> '0009N01' | Q15: =IF(B15="",IF(ISNUMBER(SEARCH("NOT NULL",UPPER(B$3))),"''","null"),SUBSTITUTE(VLOOKUP(B$2,convert!$A$1:$B$4,2,0),"@@@",B15)) -> 'カメックス' | R15: =IF(C15="",IF(ISNUMBER(SEARCH("NOT NULL",UPPER(C$3))),"''","null"),SUBSTITUTE(VLOOKUP(C$2,convert!$A$1:$B$4,2,0),"@@@",C15)) -> 79 | S15: =IF(D15="",IF(ISNUMBER(SEARCH("NOT NULL",UPPER(D$3))),"''","null"),SUBSTITUTE(VLOOKUP(D$2,convert!$A$1:$B$4,2,0),"@@@",D15)) -> 83 | T15: =IF(E15="",IF(ISNUMBER(SEARCH("NOT NULL",UPPER(E$3))),"''","null"),SUBSTITUTE(VLOOKUP(E$2,convert!$A$1:$B$4,2,0),"@@@",E15)) -> 100 | U15: =IF(F15="",IF(ISNUMBER(SEARCH("NOT NULL",UPPER(F$3))),"''","null"),SUBSTITUTE(VLOOKUP(F$2,convert!$A$1:$B$4,2,0),"@@@",F15)) -> 85 | V15: =IF(G15="",IF(ISNUMBER(SEARCH("NOT NULL",UPPER(G$3))),"''","null"),SUBSTITUTE(VLOOKUP(G$2,convert!$A$1:$B$4,2,0),"@@@",G15)) -> 105 | W15: =IF(H15="",IF(ISNUMBER(SEARCH("NOT NULL",UPPER(H$3))),"''","null"),SUBSTITUTE(VLOOKUP(H$2,convert!$A$1:$B$4,2,0),"@@@",H15)) -> 78 | ... AD15: =IF(O15="",IF(ISNUMBER(SEARCH("NOT NULL",UPPER(O$3))),"''","null"),SUBSTITUTE(VLOOKUP(O$2,convert!$A$1:$B$4,2,0),"@@@",O15)) -> TRUE | AE15: =" ("&_xlfn.TEXTJOIN(", ",FALSE,P15:AD15)&")," -> ('0009N01', 'カメックス', 79, 83, 100, 85, 105, 78, '', 'water', null, 'g1', null, null, TRUE),
A16: 0009M01 | B16: メガカメックス | C16: 79 | D16: 103 | E16: 120 | F16: 135 | G16: 115 | H16: 78 | J16: water | L16: g6 | O16: TRUE | P16: =IF(A16="",IF(ISNUMBER(SEARCH("NOT NULL",UPPER(A$3))),"''","null"),SUBSTITUTE(VLOOKUP(A$2,convert!$A$1:$B$4,2,0),"@@@",A16)) -> '0009M01' | Q16: =IF(B16="",IF(ISNUMBER(SEARCH("NOT NULL",UPPER(B$3))),"''","null"),SUBSTITUTE(VLOOKUP(B$2,convert!$A$1:$B$4,2,0),"@@@",B16)) -> 'メガカメックス' | R16: =IF(C16="",IF(ISNUMBER(SEARCH("NOT NULL",UPPER(C$3))),"''","null"),SUBSTITUTE(VLOOKUP(C$2,convert!$A$1:$B$4,2,0),"@@@",C16)) -> 79 | S16: =IF(D16="",IF(ISNUMBER(SEARCH("NOT NULL",UPPER(D$3))),"''","null"),SUBSTITUTE(VLOOKUP(D$2,convert!$A$1:$B$4,2,0),"@@@",D16)) -> 103 | T16: =IF(E16="",IF(ISNUMBER(SEARCH("NOT NULL",UPPER(E$3))),"''","null"),SUBSTITUTE(VLOOKUP(E$2,convert!$A$1:$B$4,2,0),"@@@",E16)) -> 120 | U16: =IF(F16="",IF(ISNUMBER(SEARCH("NOT NULL",UPPER(F$3))),"''","null"),SUBSTITUTE(VLOOKUP(F$2,convert!$A$1:$B$4,2,0),"@@@",F16)) -> 135 | V16: =IF(G16="",IF(ISNUMBER(SEARCH("NOT NULL",UPPER(G$3))),"''","null"),SUBSTITUTE(VLOOKUP(G$2,convert!$A$1:$B$4,2,0),"@@@",G16)) -> 115 | W16: =IF(H16="",IF(ISNUMBER(SEARCH("NOT NULL",UPPER(H$3))),"''","null"),SUBSTITUTE(VLOOKUP(H$2,convert!$A$1:$B$4,2,0),"@@@",H16)) -> 78 | ... AD16: =IF(O16="",IF(ISNUMBER(SEARCH("NOT NULL",UPPER(O$3))),"''","null"),SUBSTITUTE(VLOOKUP(O$2,convert!$A$1:$B$4,2,0),"@@@",O16)) -> TRUE | AE16: =" ("&_xlfn.TEXTJOIN(", ",FALSE,P16:AD16)&")," -> ('0009M01', 'メガカメックス', 79, 103, 120, 135, 115, 78, '', 'water', null, 'g6', null, null, TRUE),
A17: 0010N01 | B17: キャタピー | C17: 45 | D17: 30 | E17: 35 | F17: 20 | G17: 20 | H17: 45 | J17: bug | L17: g1 | O17: TRUE | P17: =IF(A17="",IF(ISNUMBER(SEARCH("NOT NULL",UPPER(A$3))),"''","null"),SUBSTITUTE(VLOOKUP(A$2,convert!$A$1:$B$4,2,0),"@@@",A17)) -> '0010N01' | Q17: =IF(B17="",IF(ISNUMBER(SEARCH("NOT NULL",UPPER(B$3))),"''","null"),SUBSTITUTE(VLOOKUP(B$2,convert!$A$1:$B$4,2,0),"@@@",B17)) -> 'キャタピー' | R17: =IF(C17="",IF(ISNUMBER(SEARCH("NOT NULL",UPPER(C$3))),"''","null"),SUBSTITUTE(VLOOKUP(C$2,convert!$A$1:$B$4,2,0),"@@@",C17)) -> 45 | S17: =IF(D17="",IF(ISNUMBER(SEARCH("NOT NULL",UPPER(D$3))),"''","null"),SUBSTITUTE(VLOOKUP(D$2,convert!$A$1:$B$4,2,0),"@@@",D17)) -> 30 | T17: =IF(E17="",IF(ISNUMBER(SEARCH("NOT NULL",UPPER(E$3))),"''","null"),SUBSTITUTE(VLOOKUP(E$2,convert!$A$1:$B$4,2,0),"@@@",E17)) -> 35 | U17: =IF(F17="",IF(ISNUMBER(SEARCH("NOT NULL",UPPER(F$3))),"''","null"),SUBSTITUTE(VLOOKUP(F$2,convert!$A$1:$B$4,2,0),"@@@",F17)) -> 20 | V17: =IF(G17="",IF(ISNUMBER(SEARCH("NOT NULL",UPPER(G$3))),"''","null"),SUBSTITUTE(VLOOKUP(G$2,convert!$A$1:$B$4,2,0),"@@@",G17)) -> 20 | W17: =IF(H17="",IF(ISNUMBER(SEARCH("NOT NULL",UPPER(H$3))),"''","null"),SUBSTITUTE(VLOOKUP(H$2,convert!$A$1:$B$4,2,0),"@@@",H17)) -> 45 | ... AD17: =IF(O17="",IF(ISNUMBER(SEARCH("NOT NULL",UPPER(O$3))),"''","null"),SUBSTITUTE(VLOOKUP(O$2,convert!$A$1:$B$4,2,0),"@@@",O17)) -> TRUE | AE17: =" ("&_xlfn.TEXTJOIN(", ",FALSE,P17:AD17)&")," -> ('0010N01', 'キャタピー', 45, 30, 35, 20, 20, 45, '', 'bug', null, 'g1', null, null, TRUE),
A18: 0011N01 | B18: トランセル | C18: 50 | D18: 20 | E18: 55 | F18: 25 | G18: 25 | H18: 30 | J18: bug | L18: g1 | O18: TRUE | P18: =IF(A18="",IF(ISNUMBER(SEARCH("NOT NULL",UPPER(A$3))),"''","null"),SUBSTITUTE(VLOOKUP(A$2,convert!$A$1:$B$4,2,0),"@@@",A18)) -> '0011N01' | Q18: =IF(B18="",IF(ISNUMBER(SEARCH("NOT NULL",UPPER(B$3))),"''","null"),SUBSTITUTE(VLOOKUP(B$2,convert!$A$1:$B$4,2,0),"@@@",B18)) -> 'トランセル' | R18: =IF(C18="",IF(ISNUMBER(SEARCH("NOT NULL",UPPER(C$3))),"''","null"),SUBSTITUTE(VLOOKUP(C$2,convert!$A$1:$B$4,2,0),"@@@",C18)) -> 50 | S18: =IF(D18="",IF(ISNUMBER(SEARCH("NOT NULL",UPPER(D$3))),"''","null"),SUBSTITUTE(VLOOKUP(D$2,convert!$A$1:$B$4,2,0),"@@@",D18)) -> 20 | T18: =IF(E18="",IF(ISNUMBER(SEARCH("NOT NULL",UPPER(E$3))),"''","null"),SUBSTITUTE(VLOOKUP(E$2,convert!$A$1:$B$4,2,0),"@@@",E18)) -> 55 | U18: =IF(F18="",IF(ISNUMBER(SEARCH("NOT NULL",UPPER(F$3))),"''","null"),SUBSTITUTE(VLOOKUP(F$2,convert!$A$1:$B$4,2,0),"@@@",F18)) -> 25 | V18: =IF(G18="",IF(ISNUMBER(SEARCH("NOT NULL",UPPER(G$3))),"''","null"),SUBSTITUTE(VLOOKUP(G$2,convert!$A$1:$B$4,2,0),"@@@",G18)) -> 25 | W18: =IF(H18="",IF(ISNUMBER(SEARCH("NOT NULL",UPPER(H$3))),"''","null"),SUBSTITUTE(VLOOKUP(H$2,convert!$A$1:$B$4,2,0),"@@@",H18)) -> 30 | ... AD18: =IF(O18="",IF(ISNUMBER(SEARCH("NOT NULL",UPPER(O$3))),"''","null"),SUBSTITUTE(VLOOKUP(O$2,convert!$A$1:$B$4,2,0),"@@@",O18)) -> TRUE | AE18: =" ("&_xlfn.TEXTJOIN(", ",FALSE,P18:AD18)&")," -> ('0011N01', 'トランセル', 50, 20, 55, 25, 25, 30, '', 'bug', null, 'g1', null, null, TRUE),
A19: 0012N01 | B19: バタフリー | C19: 60 | D19: 45 | E19: 50 | F19: 90 | G19: 80 | H19: 70 | J19: bug | K19: flying | L19: g1 | O19: TRUE | P19: =IF(A19="",IF(ISNUMBER(SEARCH("NOT NULL",UPPER(A$3))),"''","null"),SUBSTITUTE(VLOOKUP(A$2,convert!$A$1:$B$4,2,0),"@@@",A19)) -> '0012N01' | Q19: =IF(B19="",IF(ISNUMBER(SEARCH("NOT NULL",UPPER(B$3))),"''","null"),SUBSTITUTE(VLOOKUP(B$2,convert!$A$1:$B$4,2,0),"@@@",B19)) -> 'バタフリー' | R19: =IF(C19="",IF(ISNUMBER(SEARCH("NOT NULL",UPPER(C$3))),"''","null"),SUBSTITUTE(VLOOKUP(C$2,convert!$A$1:$B$4,2,0),"@@@",C19)) -> 60 | S19: =IF(D19="",IF(ISNUMBER(SEARCH("NOT NULL",UPPER(D$3))),"''","null"),SUBSTITUTE(VLOOKUP(D$2,convert!$A$1:$B$4,2,0),"@@@",D19)) -> 45 | T19: =IF(E19="",IF(ISNUMBER(SEARCH("NOT NULL",UPPER(E$3))),"''","null"),SUBSTITUTE(VLOOKUP(E$2,convert!$A$1:$B$4,2,0),"@@@",E19)) -> 50 | U19: =IF(F19="",IF(ISNUMBER(SEARCH("NOT NULL",UPPER(F$3))),"''","null"),SUBSTITUTE(VLOOKUP(F$2,convert!$A$1:$B$4,2,0),"@@@",F19)) -> 90 | V19: =IF(G19="",IF(ISNUMBER(SEARCH("NOT NULL",UPPER(G$3))),"''","null"),SUBSTITUTE(VLOOKUP(G$2,convert!$A$1:$B$4,2,0),"@@@",G19)) -> 80 | W19: =IF(H19="",IF(ISNUMBER(SEARCH("NOT NULL",UPPER(H$3))),"''","null"),SUBSTITUTE(VLOOKUP(H$2,convert!$A$1:$B$4,2,0),"@@@",H19)) -> 70 | ... AD19: =IF(O19="",IF(ISNUMBER(SEARCH("NOT NULL",UPPER(O$3))),"''","null"),SUBSTITUTE(VLOOKUP(O$2,convert!$A$1:$B$4,2,0),"@@@",O19)) -> TRUE | AE19: =" ("&_xlfn.TEXTJOIN(", ",FALSE,P19:AD19)&")," -> ('0012N01', 'バタフリー', 60, 45, 50, 90, 80, 70, '', 'bug', 'flying', 'g1', null, null, TRUE),
A20: 0013N01 | B20: ビードル | C20: 40 | D20: 35 | E20: 30 | F20: 20 | G20: 20 | H20: 50 | J20: bug | K20: poison | L20: g1 | O20: TRUE | P20: =IF(A20="",IF(ISNUMBER(SEARCH("NOT NULL",UPPER(A$3))),"''","null"),SUBSTITUTE(VLOOKUP(A$2,convert!$A$1:$B$4,2,0),"@@@",A20)) -> '0013N01' | Q20: =IF(B20="",IF(ISNUMBER(SEARCH("NOT NULL",UPPER(B$3))),"''","null"),SUBSTITUTE(VLOOKUP(B$2,convert!$A$1:$B$4,2,0),"@@@",B20)) -> 'ビードル' | R20: =IF(C20="",IF(ISNUMBER(SEARCH("NOT NULL",UPPER(C$3))),"''","null"),SUBSTITUTE(VLOOKUP(C$2,convert!$A$1:$B$4,2,0),"@@@",C20)) -> 40 | S20: =IF(D20="",IF(ISNUMBER(SEARCH("NOT NULL",UPPER(D$3))),"''","null"),SUBSTITUTE(VLOOKUP(D$2,convert!$A$1:$B$4,2,0),"@@@",D20)) -> 35 | T20: =IF(E20="",IF(ISNUMBER(SEARCH("NOT NULL",UPPER(E$3))),"''","null"),SUBSTITUTE(VLOOKUP(E$2,convert!$A$1:$B$4,2,0),"@@@",E20)) -> 30 | U20: =IF(F20="",IF(ISNUMBER(SEARCH("NOT NULL",UPPER(F$3))),"''","null"),SUBSTITUTE(VLOOKUP(F$2,convert!$A$1:$B$4,2,0),"@@@",F20)) -> 20 | V20: =IF(G20="",IF(ISNUMBER(SEARCH("NOT NULL",UPPER(G$3))),"''","null"),SUBSTITUTE(VLOOKUP(G$2,convert!$A$1:$B$4,2,0),"@@@",G20)) -> 20 | W20: =IF(H20="",IF(ISNUMBER(SEARCH("NOT NULL",UPPER(H$3))),"''","null"),SUBSTITUTE(VLOOKUP(H$2,convert!$A$1:$B$4,2,0),"@@@",H20)) -> 50 | ... AD20: =IF(O20="",IF(ISNUMBER(SEARCH("NOT NULL",UPPER(O$3))),"''","null"),SUBSTITUTE(VLOOKUP(O$2,convert!$A$1:$B$4,2,0),"@@@",O20)) -> TRUE | AE20: =" ("&_xlfn.TEXTJOIN(", ",FALSE,P20:AD20)&")," -> ('0013N01', 'ビードル', 40, 35, 30, 20, 20, 50, '', 'bug', 'poison', 'g1', null, null, TRUE),
A21: 0014N01 | B21: コクーン | C21: 45 | D21: 25 | E21: 50 | F21: 25 | G21: 25 | H21: 35 | J21: bug | K21: poison | L21: g1 | O21: TRUE | P21: =IF(A21="",IF(ISNUMBER(SEARCH("NOT NULL",UPPER(A$3))),"''","null"),SUBSTITUTE(VLOOKUP(A$2,convert!$A$1:$B$4,2,0),"@@@",A21)) -> '0014N01' | Q21: =IF(B21="",IF(ISNUMBER(SEARCH("NOT NULL",UPPER(B$3))),"''","null"),SUBSTITUTE(VLOOKUP(B$2,convert!$A$1:$B$4,2,0),"@@@",B21)) -> 'コクーン' | R21: =IF(C21="",IF(ISNUMBER(SEARCH("NOT NULL",UPPER(C$3))),"''","null"),SUBSTITUTE(VLOOKUP(C$2,convert!$A$1:$B$4,2,0),"@@@",C21)) -> 45 | S21: =IF(D21="",IF(ISNUMBER(SEARCH("NOT NULL",UPPER(D$3))),"''","null"),SUBSTITUTE(VLOOKUP(D$2,convert!$A$1:$B$4,2,0),"@@@",D21)) -> 25 | T21: =IF(E21="",IF(ISNUMBER(SEARCH("NOT NULL",UPPER(E$3))),"''","null"),SUBSTITUTE(VLOOKUP(E$2,convert!$A$1:$B$4,2,0),"@@@",E21)) -> 50 | U21: =IF(F21="",IF(ISNUMBER(SEARCH("NOT NULL",UPPER(F$3))),"''","null"),SUBSTITUTE(VLOOKUP(F$2,convert!$A$1:$B$4,2,0),"@@@",F21)) -> 25 | V21: =IF(G21="",IF(ISNUMBER(SEARCH("NOT NULL",UPPER(G$3))),"''","null"),SUBSTITUTE(VLOOKUP(G$2,convert!$A$1:$B$4,2,0),"@@@",G21)) -> 25 | W21: =IF(H21="",IF(ISNUMBER(SEARCH("NOT NULL",UPPER(H$3))),"''","null"),SUBSTITUTE(VLOOKUP(H$2,convert!$A$1:$B$4,2,0),"@@@",H21)) -> 35 | ... AD21: =IF(O21="",IF(ISNUMBER(SEARCH("NOT NULL",UPPER(O$3))),"''","null"),SUBSTITUTE(VLOOKUP(O$2,convert!$A$1:$B$4,2,0),"@@@",O21)) -> TRUE | AE21: =" ("&_xlfn.TEXTJOIN(", ",FALSE,P21:AD21)&")," -> ('0014N01', 'コクーン', 45, 25, 50, 25, 25, 35, '', 'bug', 'poison', 'g1', null, null, TRUE),
A22: 0015N01 | B22: スピアー | C22: 65 | D22: 90 | E22: 40 | F22: 45 | G22: 80 | H22: 75 | J22: bug | K22: poison | L22: g1 | O22: TRUE | P22: =IF(A22="",IF(ISNUMBER(SEARCH("NOT NULL",UPPER(A$3))),"''","null"),SUBSTITUTE(VLOOKUP(A$2,convert!$A$1:$B$4,2,0),"@@@",A22)) -> '0015N01' | Q22: =IF(B22="",IF(ISNUMBER(SEARCH("NOT NULL",UPPER(B$3))),"''","null"),SUBSTITUTE(VLOOKUP(B$2,convert!$A$1:$B$4,2,0),"@@@",B22)) -> 'スピアー' | R22: =IF(C22="",IF(ISNUMBER(SEARCH("NOT NULL",UPPER(C$3))),"''","null"),SUBSTITUTE(VLOOKUP(C$2,convert!$A$1:$B$4,2,0),"@@@",C22)) -> 65 | S22: =IF(D22="",IF(ISNUMBER(SEARCH("NOT NULL",UPPER(D$3))),"''","null"),SUBSTITUTE(VLOOKUP(D$2,convert!$A$1:$B$4,2,0),"@@@",D22)) -> 90 | T22: =IF(E22="",IF(ISNUMBER(SEARCH("NOT NULL",UPPER(E$3))),"''","null"),SUBSTITUTE(VLOOKUP(E$2,convert!$A$1:$B$4,2,0),"@@@",E22)) -> 40 | U22: =IF(F22="",IF(ISNUMBER(SEARCH("NOT NULL",UPPER(F$3))),"''","null"),SUBSTITUTE(VLOOKUP(F$2,convert!$A$1:$B$4,2,0),"@@@",F22)) -> 45 | V22: =IF(G22="",IF(ISNUMBER(SEARCH("NOT NULL",UPPER(G$3))),"''","null"),SUBSTITUTE(VLOOKUP(G$2,convert!$A$1:$B$4,2,0),"@@@",G22)) -> 80 | W22: =IF(H22="",IF(ISNUMBER(SEARCH("NOT NULL",UPPER(H$3))),"''","null"),SUBSTITUTE(VLOOKUP(H$2,convert!$A$1:$B$4,2,0),"@@@",H22)) -> 75 | ... AD22: =IF(O22="",IF(ISNUMBER(SEARCH("NOT NULL",UPPER(O$3))),"''","null"),SUBSTITUTE(VLOOKUP(O$2,convert!$A$1:$B$4,2,0),"@@@",O22)) -> TRUE | AE22: =" ("&_xlfn.TEXTJOIN(", ",FALSE,P22:AD22)&")," -> ('0015N01', 'スピアー', 65, 90, 40, 45, 80, 75, '', 'bug', 'poison', 'g1', null, null, TRUE),
A23: 0015M01 | B23: メガスピアー | C23: 65 | D23: 150 | E23: 40 | F23: 15 | G23: 80 | H23: 145 | J23: bug | K23: poison | L23: g6oras | O23: TRUE | P23: =IF(A23="",IF(ISNUMBER(SEARCH("NOT NULL",UPPER(A$3))),"''","null"),SUBSTITUTE(VLOOKUP(A$2,convert!$A$1:$B$4,2,0),"@@@",A23)) -> '0015M01' | Q23: =IF(B23="",IF(ISNUMBER(SEARCH("NOT NULL",UPPER(B$3))),"''","null"),SUBSTITUTE(VLOOKUP(B$2,convert!$A$1:$B$4,2,0),"@@@",B23)) -> 'メガスピアー' | R23: =IF(C23="",IF(ISNUMBER(SEARCH("NOT NULL",UPPER(C$3))),"''","null"),SUBSTITUTE(VLOOKUP(C$2,convert!$A$1:$B$4,2,0),"@@@",C23)) -> 65 | S23: =IF(D23="",IF(ISNUMBER(SEARCH("NOT NULL",UPPER(D$3))),"''","null"),SUBSTITUTE(VLOOKUP(D$2,convert!$A$1:$B$4,2,0),"@@@",D23)) -> 150 | T23: =IF(E23="",IF(ISNUMBER(SEARCH("NOT NULL",UPPER(E$3))),"''","null"),SUBSTITUTE(VLOOKUP(E$2,convert!$A$1:$B$4,2,0),"@@@",E23)) -> 40 | U23: =IF(F23="",IF(ISNUMBER(SEARCH("NOT NULL",UPPER(F$3))),"''","null"),SUBSTITUTE(VLOOKUP(F$2,convert!$A$1:$B$4,2,0),"@@@",F23)) -> 15 | V23: =IF(G23="",IF(ISNUMBER(SEARCH("NOT NULL",UPPER(G$3))),"''","null"),SUBSTITUTE(VLOOKUP(G$2,convert!$A$1:$B$4,2,0),"@@@",G23)) -> 80 | W23: =IF(H23="",IF(ISNUMBER(SEARCH("NOT NULL",UPPER(H$3))),"''","null"),SUBSTITUTE(VLOOKUP(H$2,convert!$A$1:$B$4,2,0),"@@@",H23)) -> 145 | ... AD23: =IF(O23="",IF(ISNUMBER(SEARCH("NOT NULL",UPPER(O$3))),"''","null"),SUBSTITUTE(VLOOKUP(O$2,convert!$A$1:$B$4,2,0),"@@@",O23)) -> TRUE | AE23: =" ("&_xlfn.TEXTJOIN(", ",FALSE,P23:AD23)&")," -> ('0015M01', 'メガスピアー', 65, 150, 40, 15, 80, 145, '', 'bug', 'poison', 'g6oras', null, null, TRUE),
A24: 0016N01 | B24: ポッポ | C24: 40 | D24: 45 | E24: 40 | F24: 35 | G24: 35 | H24: 56 | J24: normal | K24: flying | L24: g1 | O24: TRUE | P24: =IF(A24="",IF(ISNUMBER(SEARCH("NOT NULL",UPPER(A$3))),"''","null"),SUBSTITUTE(VLOOKUP(A$2,convert!$A$1:$B$4,2,0),"@@@",A24)) -> '0016N01' | Q24: =IF(B24="",IF(ISNUMBER(SEARCH("NOT NULL",UPPER(B$3))),"''","null"),SUBSTITUTE(VLOOKUP(B$2,convert!$A$1:$B$4,2,0),"@@@",B24)) -> 'ポッポ' | R24: =IF(C24="",IF(ISNUMBER(SEARCH("NOT NULL",UPPER(C$3))),"''","null"),SUBSTITUTE(VLOOKUP(C$2,convert!$A$1:$B$4,2,0),"@@@",C24)) -> 40 | S24: =IF(D24="",IF(ISNUMBER(SEARCH("NOT NULL",UPPER(D$3))),"''","null"),SUBSTITUTE(VLOOKUP(D$2,convert!$A$1:$B$4,2,0),"@@@",D24)) -> 45 | T24: =IF(E24="",IF(ISNUMBER(SEARCH("NOT NULL",UPPER(E$3))),"''","null"),SUBSTITUTE(VLOOKUP(E$2,convert!$A$1:$B$4,2,0),"@@@",E24)) -> 40 | U24: =IF(F24="",IF(ISNUMBER(SEARCH("NOT NULL",UPPER(F$3))),"''","null"),SUBSTITUTE(VLOOKUP(F$2,convert!$A$1:$B$4,2,0),"@@@",F24)) -> 35 | V24: =IF(G24="",IF(ISNUMBER(SEARCH("NOT NULL",UPPER(G$3))),"''","null"),SUBSTITUTE(VLOOKUP(G$2,convert!$A$1:$B$4,2,0),"@@@",G24)) -> 35 | W24: =IF(H24="",IF(ISNUMBER(SEARCH("NOT NULL",UPPER(H$3))),"''","null"),SUBSTITUTE(VLOOKUP(H$2,convert!$A$1:$B$4,2,0),"@@@",H24)) -> 56 | ... AD24: =IF(O24="",IF(ISNUMBER(SEARCH("NOT NULL",UPPER(O$3))),"''","null"),SUBSTITUTE(VLOOKUP(O$2,convert!$A$1:$B$4,2,0),"@@@",O24)) -> TRUE | AE24: =" ("&_xlfn.TEXTJOIN(", ",FALSE,P24:AD24)&")," -> ('0016N01', 'ポッポ', 40, 45, 40, 35, 35, 56, '', 'normal', 'flying', 'g1', null, null, TRUE),
A25: 0017N01 | B25: ピジョン | C25: 63 | D25: 60 | E25: 55 | F25: 50 | G25: 50 | H25: 71 | J25: normal | K25: flying | L25: g1 | O25: TRUE | P25: =IF(A25="",IF(ISNUMBER(SEARCH("NOT NULL",UPPER(A$3))),"''","null"),SUBSTITUTE(VLOOKUP(A$2,convert!$A$1:$B$4,2,0),"@@@",A25)) -> '0017N01' | Q25: =IF(B25="",IF(ISNUMBER(SEARCH("NOT NULL",UPPER(B$3))),"''","null"),SUBSTITUTE(VLOOKUP(B$2,convert!$A$1:$B$4,2,0),"@@@",B25)) -> 'ピジョン' | R25: =IF(C25="",IF(ISNUMBER(SEARCH("NOT NULL",UPPER(C$3))),"''","null"),SUBSTITUTE(VLOOKUP(C$2,convert!$A$1:$B$4,2,0),"@@@",C25)) -> 63 | S25: =IF(D25="",IF(ISNUMBER(SEARCH("NOT NULL",UPPER(D$3))),"''","null"),SUBSTITUTE(VLOOKUP(D$2,convert!$A$1:$B$4,2,0),"@@@",D25)) -> 60 | T25: =IF(E25="",IF(ISNUMBER(SEARCH("NOT NULL",UPPER(E$3))),"''","null"),SUBSTITUTE(VLOOKUP(E$2,convert!$A$1:$B$4,2,0),"@@@",E25)) -> 55 | U25: =IF(F25="",IF(ISNUMBER(SEARCH("NOT NULL",UPPER(F$3))),"''","null"),SUBSTITUTE(VLOOKUP(F$2,convert!$A$1:$B$4,2,0),"@@@",F25)) -> 50 | V25: =IF(G25="",IF(ISNUMBER(SEARCH("NOT NULL",UPPER(G$3))),"''","null"),SUBSTITUTE(VLOOKUP(G$2,convert!$A$1:$B$4,2,0),"@@@",G25)) -> 50 | W25: =IF(H25="",IF(ISNUMBER(SEARCH("NOT NULL",UPPER(H$3))),"''","null"),SUBSTITUTE(VLOOKUP(H$2,convert!$A$1:$B$4,2,0),"@@@",H25)) -> 71 | ... AD25: =IF(O25="",IF(ISNUMBER(SEARCH("NOT NULL",UPPER(O$3))),"''","null"),SUBSTITUTE(VLOOKUP(O$2,convert!$A$1:$B$4,2,0),"@@@",O25)) -> TRUE | AE25: =" ("&_xlfn.TEXTJOIN(", ",FALSE,P25:AD25)&")," -> ('0017N01', 'ピジョン', 63, 60, 55, 50, 50, 71, '', 'normal', 'flying', 'g1', null, null, TRUE),
A26: 0018N01 | B26: ピジョット | C26: 83 | D26: 80 | E26: 75 | F26: 70 | G26: 70 | H26: 101 | J26: normal | K26: flying | L26: g1 | O26: TRUE | P26: =IF(A26="",IF(ISNUMBER(SEARCH("NOT NULL",UPPER(A$3))),"''","null"),SUBSTITUTE(VLOOKUP(A$2,convert!$A$1:$B$4,2,0),"@@@",A26)) -> '0018N01' | Q26: =IF(B26="",IF(ISNUMBER(SEARCH("NOT NULL",UPPER(B$3))),"''","null"),SUBSTITUTE(VLOOKUP(B$2,convert!$A$1:$B$4,2,0),"@@@",B26)) -> 'ピジョット' | R26: =IF(C26="",IF(ISNUMBER(SEARCH("NOT NULL",UPPER(C$3))),"''","null"),SUBSTITUTE(VLOOKUP(C$2,convert!$A$1:$B$4,2,0),"@@@",C26)) -> 83 | S26: =IF(D26="",IF(ISNUMBER(SEARCH("NOT NULL",UPPER(D$3))),"''","null"),SUBSTITUTE(VLOOKUP(D$2,convert!$A$1:$B$4,2,0),"@@@",D26)) -> 80 | T26: =IF(E26="",IF(ISNUMBER(SEARCH("NOT NULL",UPPER(E$3))),"''","null"),SUBSTITUTE(VLOOKUP(E$2,convert!$A$1:$B$4,2,0),"@@@",E26)) -> 75 | U26: =IF(F26="",IF(ISNUMBER(SEARCH("NOT NULL",UPPER(F$3))),"''","null"),SUBSTITUTE(VLOOKUP(F$2,convert!$A$1:$B$4,2,0),"@@@",F26)) -> 70 | V26: =IF(G26="",IF(ISNUMBER(SEARCH("NOT NULL",UPPER(G$3))),"''","null"),SUBSTITUTE(VLOOKUP(G$2,convert!$A$1:$B$4,2,0),"@@@",G26)) -> 70 | W26: =IF(H26="",IF(ISNUMBER(SEARCH("NOT NULL",UPPER(H$3))),"''","null"),SUBSTITUTE(VLOOKUP(H$2,convert!$A$1:$B$4,2,0),"@@@",H26)) -> 101 | ... AD26: =IF(O26="",IF(ISNUMBER(SEARCH("NOT NULL",UPPER(O$3))),"''","null"),SUBSTITUTE(VLOOKUP(O$2,convert!$A$1:$B$4,2,0),"@@@",O26)) -> TRUE | AE26: =" ("&_xlfn.TEXTJOIN(", ",FALSE,P26:AD26)&")," -> ('0018N01', 'ピジョット', 83, 80, 75, 70, 70, 101, '', 'normal', 'flying', 'g1', null, null, TRUE),
A27: 0018M01 | B27: メガピジョット | C27: 83 | D27: 80 | E27: 80 | F27: 135 | G27: 80 | H27: 121 | J27: normal | K27: flying | L27: g6oras | O27: TRUE | P27: =IF(A27="",IF(ISNUMBER(SEARCH("NOT NULL",UPPER(A$3))),"''","null"),SUBSTITUTE(VLOOKUP(A$2,convert!$A$1:$B$4,2,0),"@@@",A27)) -> '0018M01' | Q27: =IF(B27="",IF(ISNUMBER(SEARCH("NOT NULL",UPPER(B$3))),"''","null"),SUBSTITUTE(VLOOKUP(B$2,convert!$A$1:$B$4,2,0),"@@@",B27)) -> 'メガピジョット' | R27: =IF(C27="",IF(ISNUMBER(SEARCH("NOT NULL",UPPER(C$3))),"''","null"),SUBSTITUTE(VLOOKUP(C$2,convert!$A$1:$B$4,2,0),"@@@",C27)) -> 83 | S27: =IF(D27="",IF(ISNUMBER(SEARCH("NOT NULL",UPPER(D$3))),"''","null"),SUBSTITUTE(VLOOKUP(D$2,convert!$A$1:$B$4,2,0),"@@@",D27)) -> 80 | T27: =IF(E27="",IF(ISNUMBER(SEARCH("NOT NULL",UPPER(E$3))),"''","null"),SUBSTITUTE(VLOOKUP(E$2,convert!$A$1:$B$4,2,0),"@@@",E27)) -> 80 | U27: =IF(F27="",IF(ISNUMBER(SEARCH("NOT NULL",UPPER(F$3))),"''","null"),SUBSTITUTE(VLOOKUP(F$2,convert!$A$1:$B$4,2,0),"@@@",F27)) -> 135 | V27: =IF(G27="",IF(ISNUMBER(SEARCH("NOT NULL",UPPER(G$3))),"''","null"),SUBSTITUTE(VLOOKUP(G$2,convert!$A$1:$B$4,2,0),"@@@",G27)) -> 80 | W27: =IF(H27="",IF(ISNUMBER(SEARCH("NOT NULL",UPPER(H$3))),"''","null"),SUBSTITUTE(VLOOKUP(H$2,convert!$A$1:$B$4,2,0),"@@@",H27)) -> 121 | ... AD27: =IF(O27="",IF(ISNUMBER(SEARCH("NOT NULL",UPPER(O$3))),"''","null"),SUBSTITUTE(VLOOKUP(O$2,convert!$A$1:$B$4,2,0),"@@@",O27)) -> TRUE | AE27: =" ("&_xlfn.TEXTJOIN(", ",FALSE,P27:AD27)&")," -> ('0018M01', 'メガピジョット', 83, 80, 80, 135, 80, 121, '', 'normal', 'flying', 'g6oras', null, null, TRUE),
A28: 0019N01 | B28: コラッタ | C28: 30 | D28: 56 | E28: 35 | F28: 25 | G28: 35 | H28: 72 | J28: normal | L28: g1 | O28: TRUE | P28: =IF(A28="",IF(ISNUMBER(SEARCH("NOT NULL",UPPER(A$3))),"''","null"),SUBSTITUTE(VLOOKUP(A$2,convert!$A$1:$B$4,2,0),"@@@",A28)) -> '0019N01' | Q28: =IF(B28="",IF(ISNUMBER(SEARCH("NOT NULL",UPPER(B$3))),"''","null"),SUBSTITUTE(VLOOKUP(B$2,convert!$A$1:$B$4,2,0),"@@@",B28)) -> 'コラッタ' | R28: =IF(C28="",IF(ISNUMBER(SEARCH("NOT NULL",UPPER(C$3))),"''","null"),SUBSTITUTE(VLOOKUP(C$2,convert!$A$1:$B$4,2,0),"@@@",C28)) -> 30 | S28: =IF(D28="",IF(ISNUMBER(SEARCH("NOT NULL",UPPER(D$3))),"''","null"),SUBSTITUTE(VLOOKUP(D$2,convert!$A$1:$B$4,2,0),"@@@",D28)) -> 56 | T28: =IF(E28="",IF(ISNUMBER(SEARCH("NOT NULL",UPPER(E$3))),"''","null"),SUBSTITUTE(VLOOKUP(E$2,convert!$A$1:$B$4,2,0),"@@@",E28)) -> 35 | U28: =IF(F28="",IF(ISNUMBER(SEARCH("NOT NULL",UPPER(F$3))),"''","null"),SUBSTITUTE(VLOOKUP(F$2,convert!$A$1:$B$4,2,0),"@@@",F28)) -> 25 | V28: =IF(G28="",IF(ISNUMBER(SEARCH("NOT NULL",UPPER(G$3))),"''","null"),SUBSTITUTE(VLOOKUP(G$2,convert!$A$1:$B$4,2,0),"@@@",G28)) -> 35 | W28: =IF(H28="",IF(ISNUMBER(SEARCH("NOT NULL",UPPER(H$3))),"''","null"),SUBSTITUTE(VLOOKUP(H$2,convert!$A$1:$B$4,2,0),"@@@",H28)) -> 72 | ... AD28: =IF(O28="",IF(ISNUMBER(SEARCH("NOT NULL",UPPER(O$3))),"''","null"),SUBSTITUTE(VLOOKUP(O$2,convert!$A$1:$B$4,2,0),"@@@",O28)) -> TRUE | AE28: =" ("&_xlfn.TEXTJOIN(", ",FALSE,P28:AD28)&")," -> ('0019N01', 'コラッタ', 30, 56, 35, 25, 35, 72, '', 'normal', null, 'g1', null, null, TRUE),
A29: 0019A01 | B29: コラッタ | C29: 30 | D29: 56 | E29: 35 | F29: 25 | G29: 35 | H29: 72 | I29: アローラのすがた | J29: dark | K29: normal | L29: g7 | O29: TRUE | P29: =IF(A29="",IF(ISNUMBER(SEARCH("NOT NULL",UPPER(A$3))),"''","null"),SUBSTITUTE(VLOOKUP(A$2,convert!$A$1:$B$4,2,0),"@@@",A29)) -> '0019A01' | Q29: =IF(B29="",IF(ISNUMBER(SEARCH("NOT NULL",UPPER(B$3))),"''","null"),SUBSTITUTE(VLOOKUP(B$2,convert!$A$1:$B$4,2,0),"@@@",B29)) -> 'コラッタ' | R29: =IF(C29="",IF(ISNUMBER(SEARCH("NOT NULL",UPPER(C$3))),"''","null"),SUBSTITUTE(VLOOKUP(C$2,convert!$A$1:$B$4,2,0),"@@@",C29)) -> 30 | S29: =IF(D29="",IF(ISNUMBER(SEARCH("NOT NULL",UPPER(D$3))),"''","null"),SUBSTITUTE(VLOOKUP(D$2,convert!$A$1:$B$4,2,0),"@@@",D29)) -> 56 | T29: =IF(E29="",IF(ISNUMBER(SEARCH("NOT NULL",UPPER(E$3))),"''","null"),SUBSTITUTE(VLOOKUP(E$2,convert!$A$1:$B$4,2,0),"@@@",E29)) -> 35 | U29: =IF(F29="",IF(ISNUMBER(SEARCH("NOT NULL",UPPER(F$3))),"''","null"),SUBSTITUTE(VLOOKUP(F$2,convert!$A$1:$B$4,2,0),"@@@",F29)) -> 25 | V29: =IF(G29="",IF(ISNUMBER(SEARCH("NOT NULL",UPPER(G$3))),"''","null"),SUBSTITUTE(VLOOKUP(G$2,convert!$A$1:$B$4,2,0),"@@@",G29)) -> 35 | W29: =IF(H29="",IF(ISNUMBER(SEARCH("NOT NULL",UPPER(H$3))),"''","null"),SUBSTITUTE(VLOOKUP(H$2,convert!$A$1:$B$4,2,0),"@@@",H29)) -> 72 | ... AD29: =IF(O29="",IF(ISNUMBER(SEARCH("NOT NULL",UPPER(O$3))),"''","null"),SUBSTITUTE(VLOOKUP(O$2,convert!$A$1:$B$4,2,0),"@@@",O29)) -> TRUE | AE29: =" ("&_xlfn.TEXTJOIN(", ",FALSE,P29:AD29)&")," -> ('0019A01', 'コラッタ', 30, 56, 35, 25, 35, 72, 'アローラのすがた', 'dark', 'normal', 'g7', null, null, TRUE),
A30: 0020N01 | B30: ラッタ | C30: 55 | D30: 81 | E30: 60 | F30: 50 | G30: 70 | H30: 97 | J30: normal | L30: g1 | O30: TRUE | P30: =IF(A30="",IF(ISNUMBER(SEARCH("NOT NULL",UPPER(A$3))),"''","null"),SUBSTITUTE(VLOOKUP(A$2,convert!$A$1:$B$4,2,0),"@@@",A30)) -> '0020N01' | Q30: =IF(B30="",IF(ISNUMBER(SEARCH("NOT NULL",UPPER(B$3))),"''","null"),SUBSTITUTE(VLOOKUP(B$2,convert!$A$1:$B$4,2,0),"@@@",B30)) -> 'ラッタ' | R30: =IF(C30="",IF(ISNUMBER(SEARCH("NOT NULL",UPPER(C$3))),"''","null"),SUBSTITUTE(VLOOKUP(C$2,convert!$A$1:$B$4,2,0),"@@@",C30)) -> 55 | S30: =IF(D30="",IF(ISNUMBER(SEARCH("NOT NULL",UPPER(D$3))),"''","null"),SUBSTITUTE(VLOOKUP(D$2,convert!$A$1:$B$4,2,0),"@@@",D30)) -> 81 | T30: =IF(E30="",IF(ISNUMBER(SEARCH("NOT NULL",UPPER(E$3))),"''","null"),SUBSTITUTE(VLOOKUP(E$2,convert!$A$1:$B$4,2,0),"@@@",E30)) -> 60 | U30: =IF(F30="",IF(ISNUMBER(SEARCH("NOT NULL",UPPER(F$3))),"''","null"),SUBSTITUTE(VLOOKUP(F$2,convert!$A$1:$B$4,2,0),"@@@",F30)) -> 50 | V30: =IF(G30="",IF(ISNUMBER(SEARCH("NOT NULL",UPPER(G$3))),"''","null"),SUBSTITUTE(VLOOKUP(G$2,convert!$A$1:$B$4,2,0),"@@@",G30)) -> 70 | W30: =IF(H30="",IF(ISNUMBER(SEARCH("NOT NULL",UPPER(H$3))),"''","null"),SUBSTITUTE(VLOOKUP(H$2,convert!$A$1:$B$4,2,0),"@@@",H30)) -> 97 | ... AD30: =IF(O30="",IF(ISNUMBER(SEARCH("NOT NULL",UPPER(O$3))),"''","null"),SUBSTITUTE(VLOOKUP(O$2,convert!$A$1:$B$4,2,0),"@@@",O30)) -> TRUE | AE30: =" ("&_xlfn.TEXTJOIN(", ",FALSE,P30:AD30)&")," -> ('0020N01', 'ラッタ', 55, 81, 60, 50, 70, 97, '', 'normal', null, 'g1', null, null, TRUE),
A31: 0020A01 | B31: ラッタ | C31: 75 | D31: 71 | E31: 70 | F31: 40 | G31: 80 | H31: 77 | I31: アローラのすがた | J31: dark | K31: normal | L31: g7 | O31: TRUE | P31: =IF(A31="",IF(ISNUMBER(SEARCH("NOT NULL",UPPER(A$3))),"''","null"),SUBSTITUTE(VLOOKUP(A$2,convert!$A$1:$B$4,2,0),"@@@",A31)) -> '0020A01' | Q31: =IF(B31="",IF(ISNUMBER(SEARCH("NOT NULL",UPPER(B$3))),"''","null"),SUBSTITUTE(VLOOKUP(B$2,convert!$A$1:$B$4,2,0),"@@@",B31)) -> 'ラッタ' | R31: =IF(C31="",IF(ISNUMBER(SEARCH("NOT NULL",UPPER(C$3))),"''","null"),SUBSTITUTE(VLOOKUP(C$2,convert!$A$1:$B$4,2,0),"@@@",C31)) -> 75 | S31: =IF(D31="",IF(ISNUMBER(SEARCH("NOT NULL",UPPER(D$3))),"''","null"),SUBSTITUTE(VLOOKUP(D$2,convert!$A$1:$B$4,2,0),"@@@",D31)) -> 71 | T31: =IF(E31="",IF(ISNUMBER(SEARCH("NOT NULL",UPPER(E$3))),"''","null"),SUBSTITUTE(VLOOKUP(E$2,convert!$A$1:$B$4,2,0),"@@@",E31)) -> 70 | U31: =IF(F31="",IF(ISNUMBER(SEARCH("NOT NULL",UPPER(F$3))),"''","null"),SUBSTITUTE(VLOOKUP(F$2,convert!$A$1:$B$4,2,0),"@@@",F31)) -> 40 | V31: =IF(G31="",IF(ISNUMBER(SEARCH("NOT NULL",UPPER(G$3))),"''","null"),SUBSTITUTE(VLOOKUP(G$2,convert!$A$1:$B$4,2,0),"@@@",G31)) -> 80 | W31: =IF(H31="",IF(ISNUMBER(SEARCH("NOT NULL",UPPER(H$3))),"''","null"),SUBSTITUTE(VLOOKUP(H$2,convert!$A$1:$B$4,2,0),"@@@",H31)) -> 77 | ... AD31: =IF(O31="",IF(ISNUMBER(SEARCH("NOT NULL",UPPER(O$3))),"''","null"),SUBSTITUTE(VLOOKUP(O$2,convert!$A$1:$B$4,2,0),"@@@",O31)) -> TRUE | AE31: =" ("&_xlfn.TEXTJOIN(", ",FALSE,P31:AD31)&")," -> ('0020A01', 'ラッタ', 75, 71, 70, 40, 80, 77, 'アローラのすがた', 'dark', 'normal', 'g7', null, null, TRUE),
A32: 0021N01 | B32: オニスズメ | C32: 40 | D32: 60 | E32: 30 | F32: 31 | G32: 31 | H32: 70 | J32: normal | K32: flying | L32: g1 | O32: TRUE | P32: =IF(A32="",IF(ISNUMBER(SEARCH("NOT NULL",UPPER(A$3))),"''","null"),SUBSTITUTE(VLOOKUP(A$2,convert!$A$1:$B$4,2,0),"@@@",A32)) -> '0021N01' | Q32: =IF(B32="",IF(ISNUMBER(SEARCH("NOT NULL",UPPER(B$3))),"''","null"),SUBSTITUTE(VLOOKUP(B$2,convert!$A$1:$B$4,2,0),"@@@",B32)) -> 'オニスズメ' | R32: =IF(C32="",IF(ISNUMBER(SEARCH("NOT NULL",UPPER(C$3))),"''","null"),SUBSTITUTE(VLOOKUP(C$2,convert!$A$1:$B$4,2,0),"@@@",C32)) -> 40 | S32: =IF(D32="",IF(ISNUMBER(SEARCH("NOT NULL",UPPER(D$3))),"''","null"),SUBSTITUTE(VLOOKUP(D$2,convert!$A$1:$B$4,2,0),"@@@",D32)) -> 60 | T32: =IF(E32="",IF(ISNUMBER(SEARCH("NOT NULL",UPPER(E$3))),"''","null"),SUBSTITUTE(VLOOKUP(E$2,convert!$A$1:$B$4,2,0),"@@@",E32)) -> 30 | U32: =IF(F32="",IF(ISNUMBER(SEARCH("NOT NULL",UPPER(F$3))),"''","null"),SUBSTITUTE(VLOOKUP(F$2,convert!$A$1:$B$4,2,0),"@@@",F32)) -> 31 | V32: =IF(G32="",IF(ISNUMBER(SEARCH("NOT NULL",UPPER(G$3))),"''","null"),SUBSTITUTE(VLOOKUP(G$2,convert!$A$1:$B$4,2,0),"@@@",G32)) -> 31 | W32: =IF(H32="",IF(ISNUMBER(SEARCH("NOT NULL",UPPER(H$3))),"''","null"),SUBSTITUTE(VLOOKUP(H$2,convert!$A$1:$B$4,2,0),"@@@",H32)) -> 70 | ... AD32: =IF(O32="",IF(ISNUMBER(SEARCH("NOT NULL",UPPER(O$3))),"''","null"),SUBSTITUTE(VLOOKUP(O$2,convert!$A$1:$B$4,2,0),"@@@",O32)) -> TRUE | AE32: =" ("&_xlfn.TEXTJOIN(", ",FALSE,P32:AD32)&")," -> ('0021N01', 'オニスズメ', 40, 60, 30, 31, 31, 70, '', 'normal', 'flying', 'g1', null, null, TRUE),
A33: 0022N01 | B33: オニドリル | C33: 65 | D33: 90 | E33: 65 | F33: 61 | G33: 61 | H33: 100 | J33: normal | K33: flying | L33: g1 | O33: TRUE | P33: =IF(A33="",IF(ISNUMBER(SEARCH("NOT NULL",UPPER(A$3))),"''","null"),SUBSTITUTE(VLOOKUP(A$2,convert!$A$1:$B$4,2,0),"@@@",A33)) -> '0022N01' | Q33: =IF(B33="",IF(ISNUMBER(SEARCH("NOT NULL",UPPER(B$3))),"''","null"),SUBSTITUTE(VLOOKUP(B$2,convert!$A$1:$B$4,2,0),"@@@",B33)) -> 'オニドリル' | R33: =IF(C33="",IF(ISNUMBER(SEARCH("NOT NULL",UPPER(C$3))),"''","null"),SUBSTITUTE(VLOOKUP(C$2,convert!$A$1:$B$4,2,0),"@@@",C33)) -> 65 | S33: =IF(D33="",IF(ISNUMBER(SEARCH("NOT NULL",UPPER(D$3))),"''","null"),SUBSTITUTE(VLOOKUP(D$2,convert!$A$1:$B$4,2,0),"@@@",D33)) -> 90 | T33: =IF(E33="",IF(ISNUMBER(SEARCH("NOT NULL",UPPER(E$3))),"''","null"),SUBSTITUTE(VLOOKUP(E$2,convert!$A$1:$B$4,2,0),"@@@",E33)) -> 65 | U33: =IF(F33="",IF(ISNUMBER(SEARCH("NOT NULL",UPPER(F$3))),"''","null"),SUBSTITUTE(VLOOKUP(F$2,convert!$A$1:$B$4,2,0),"@@@",F33)) -> 61 | V33: =IF(G33="",IF(ISNUMBER(SEARCH("NOT NULL",UPPER(G$3))),"''","null"),SUBSTITUTE(VLOOKUP(G$2,convert!$A$1:$B$4,2,0),"@@@",G33)) -> 61 | W33: =IF(H33="",IF(ISNUMBER(SEARCH("NOT NULL",UPPER(H$3))),"''","null"),SUBSTITUTE(VLOOKUP(H$2,convert!$A$1:$B$4,2,0),"@@@",H33)) -> 100 | ... AD33: =IF(O33="",IF(ISNUMBER(SEARCH("NOT NULL",UPPER(O$3))),"''","null"),SUBSTITUTE(VLOOKUP(O$2,convert!$A$1:$B$4,2,0),"@@@",O33)) -> TRUE | AE33: =" ("&_xlfn.TEXTJOIN(", ",FALSE,P33:AD33)&")," -> ('0022N01', 'オニドリル', 65, 90, 65, 61, 61, 100, '', 'normal', 'flying', 'g1', null, null, TRUE),
A34: 0023N01 | B34: アーボ | C34: 35 | D34: 60 | E34: 44 | F34: 40 | G34: 54 | H34: 55 | J34: poison | L34: g1 | O34: TRUE | P34: =IF(A34="",IF(ISNUMBER(SEARCH("NOT NULL",UPPER(A$3))),"''","null"),SUBSTITUTE(VLOOKUP(A$2,convert!$A$1:$B$4,2,0),"@@@",A34)) -> '0023N01' | Q34: =IF(B34="",IF(ISNUMBER(SEARCH("NOT NULL",UPPER(B$3))),"''","null"),SUBSTITUTE(VLOOKUP(B$2,convert!$A$1:$B$4,2,0),"@@@",B34)) -> 'アーボ' | R34: =IF(C34="",IF(ISNUMBER(SEARCH("NOT NULL",UPPER(C$3))),"''","null"),SUBSTITUTE(VLOOKUP(C$2,convert!$A$1:$B$4,2,0),"@@@",C34)) -> 35 | S34: =IF(D34="",IF(ISNUMBER(SEARCH("NOT NULL",UPPER(D$3))),"''","null"),SUBSTITUTE(VLOOKUP(D$2,convert!$A$1:$B$4,2,0),"@@@",D34)) -> 60 | T34: =IF(E34="",IF(ISNUMBER(SEARCH("NOT NULL",UPPER(E$3))),"''","null"),SUBSTITUTE(VLOOKUP(E$2,convert!$A$1:$B$4,2,0),"@@@",E34)) -> 44 | U34: =IF(F34="",IF(ISNUMBER(SEARCH("NOT NULL",UPPER(F$3))),"''","null"),SUBSTITUTE(VLOOKUP(F$2,convert!$A$1:$B$4,2,0),"@@@",F34)) -> 40 | V34: =IF(G34="",IF(ISNUMBER(SEARCH("NOT NULL",UPPER(G$3))),"''","null"),SUBSTITUTE(VLOOKUP(G$2,convert!$A$1:$B$4,2,0),"@@@",G34)) -> 54 | W34: =IF(H34="",IF(ISNUMBER(SEARCH("NOT NULL",UPPER(H$3))),"''","null"),SUBSTITUTE(VLOOKUP(H$2,convert!$A$1:$B$4,2,0),"@@@",H34)) -> 55 | ... AD34: =IF(O34="",IF(ISNUMBER(SEARCH("NOT NULL",UPPER(O$3))),"''","null"),SUBSTITUTE(VLOOKUP(O$2,convert!$A$1:$B$4,2,0),"@@@",O34)) -> TRUE | AE34: =" ("&_xlfn.TEXTJOIN(", ",FALSE,P34:AD34)&")," -> ('0023N01', 'アーボ', 35, 60, 44, 40, 54, 55, '', 'poison', null, 'g1', null, null, TRUE),
A35: 0024N01 | B35: アーボック | C35: 60 | D35: 95 | E35: 69 | F35: 65 | G35: 79 | H35: 80 | J35: poison | L35: g1 | O35: TRUE | P35: =IF(A35="",IF(ISNUMBER(SEARCH("NOT NULL",UPPER(A$3))),"''","null"),SUBSTITUTE(VLOOKUP(A$2,convert!$A$1:$B$4,2,0),"@@@",A35)) -> '0024N01' | Q35: =IF(B35="",IF(ISNUMBER(SEARCH("NOT NULL",UPPER(B$3))),"''","null"),SUBSTITUTE(VLOOKUP(B$2,convert!$A$1:$B$4,2,0),"@@@",B35)) -> 'アーボック' | R35: =IF(C35="",IF(ISNUMBER(SEARCH("NOT NULL",UPPER(C$3))),"''","null"),SUBSTITUTE(VLOOKUP(C$2,convert!$A$1:$B$4,2,0),"@@@",C35)) -> 60 | S35: =IF(D35="",IF(ISNUMBER(SEARCH("NOT NULL",UPPER(D$3))),"''","null"),SUBSTITUTE(VLOOKUP(D$2,convert!$A$1:$B$4,2,0),"@@@",D35)) -> 95 | T35: =IF(E35="",IF(ISNUMBER(SEARCH("NOT NULL",UPPER(E$3))),"''","null"),SUBSTITUTE(VLOOKUP(E$2,convert!$A$1:$B$4,2,0),"@@@",E35)) -> 69 | U35: =IF(F35="",IF(ISNUMBER(SEARCH("NOT NULL",UPPER(F$3))),"''","null"),SUBSTITUTE(VLOOKUP(F$2,convert!$A$1:$B$4,2,0),"@@@",F35)) -> 65 | V35: =IF(G35="",IF(ISNUMBER(SEARCH("NOT NULL",UPPER(G$3))),"''","null"),SUBSTITUTE(VLOOKUP(G$2,convert!$A$1:$B$4,2,0),"@@@",G35)) -> 79 | W35: =IF(H35="",IF(ISNUMBER(SEARCH("NOT NULL",UPPER(H$3))),"''","null"),SUBSTITUTE(VLOOKUP(H$2,convert!$A$1:$B$4,2,0),"@@@",H35)) -> 80 | ... AD35: =IF(O35="",IF(ISNUMBER(SEARCH("NOT NULL",UPPER(O$3))),"''","null"),SUBSTITUTE(VLOOKUP(O$2,convert!$A$1:$B$4,2,0),"@@@",O35)) -> TRUE | AE35: =" ("&_xlfn.TEXTJOIN(", ",FALSE,P35:AD35)&")," -> ('0024N01', 'アーボック', 60, 95, 69, 65, 79, 80, '', 'poison', null, 'g1', null, null, TRUE),
A36: 0025N01 | B36: ピカチュウ | C36: 35 | D36: 55 | E36: 40 | F36: 50 | G36: 50 | H36: 90 | J36: electric | L36: g1 | O36: TRUE | P36: =IF(A36="",IF(ISNUMBER(SEARCH("NOT NULL",UPPER(A$3))),"''","null"),SUBSTITUTE(VLOOKUP(A$2,convert!$A$1:$B$4,2,0),"@@@",A36)) -> '0025N01' | Q36: =IF(B36="",IF(ISNUMBER(SEARCH("NOT NULL",UPPER(B$3))),"''","null"),SUBSTITUTE(VLOOKUP(B$2,convert!$A$1:$B$4,2,0),"@@@",B36)) -> 'ピカチュウ' | R36: =IF(C36="",IF(ISNUMBER(SEARCH("NOT NULL",UPPER(C$3))),"''","null"),SUBSTITUTE(VLOOKUP(C$2,convert!$A$1:$B$4,2,0),"@@@",C36)) -> 35 | S36: =IF(D36="",IF(ISNUMBER(SEARCH("NOT NULL",UPPER(D$3))),"''","null"),SUBSTITUTE(VLOOKUP(D$2,convert!$A$1:$B$4,2,0),"@@@",D36)) -> 55 | T36: =IF(E36="",IF(ISNUMBER(SEARCH("NOT NULL",UPPER(E$3))),"''","null"),SUBSTITUTE(VLOOKUP(E$2,convert!$A$1:$B$4,2,0),"@@@",E36)) -> 40 | U36: =IF(F36="",IF(ISNUMBER(SEARCH("NOT NULL",UPPER(F$3))),"''","null"),SUBSTITUTE(VLOOKUP(F$2,convert!$A$1:$B$4,2,0),"@@@",F36)) -> 50 | V36: =IF(G36="",IF(ISNUMBER(SEARCH("NOT NULL",UPPER(G$3))),"''","null"),SUBSTITUTE(VLOOKUP(G$2,convert!$A$1:$B$4,2,0),"@@@",G36)) -> 50 | W36: =IF(H36="",IF(ISNUMBER(SEARCH("NOT NULL",UPPER(H$3))),"''","null"),SUBSTITUTE(VLOOKUP(H$2,convert!$A$1:$B$4,2,0),"@@@",H36)) -> 90 | ... AD36: =IF(O36="",IF(ISNUMBER(SEARCH("NOT NULL",UPPER(O$3))),"''","null"),SUBSTITUTE(VLOOKUP(O$2,convert!$A$1:$B$4,2,0),"@@@",O36)) -> TRUE | AE36: =" ("&_xlfn.TEXTJOIN(", ",FALSE,P36:AD36)&")," -> ('0025N01', 'ピカチュウ', 35, 55, 40, 50, 50, 90, '', 'electric', null, 'g1', null, null, TRUE),
A37: 0025N02 | B37: ピカチュウ | C37: 45 | D37: 80 | E37: 50 | F37: 75 | G37: 60 | H37: 120 | I37: 相棒 | J37: electric | L37: g7pv | O37: FALSE | P37: =IF(A37="",IF(ISNUMBER(SEARCH("NOT NULL",UPPER(A$3))),"''","null"),SUBSTITUTE(VLOOKUP(A$2,convert!$A$1:$B$4,2,0),"@@@",A37)) -> '0025N02' | Q37: =IF(B37="",IF(ISNUMBER(SEARCH("NOT NULL",UPPER(B$3))),"''","null"),SUBSTITUTE(VLOOKUP(B$2,convert!$A$1:$B$4,2,0),"@@@",B37)) -> 'ピカチュウ' | R37: =IF(C37="",IF(ISNUMBER(SEARCH("NOT NULL",UPPER(C$3))),"''","null"),SUBSTITUTE(VLOOKUP(C$2,convert!$A$1:$B$4,2,0),"@@@",C37)) -> 45 | S37: =IF(D37="",IF(ISNUMBER(SEARCH("NOT NULL",UPPER(D$3))),"''","null"),SUBSTITUTE(VLOOKUP(D$2,convert!$A$1:$B$4,2,0),"@@@",D37)) -> 80 | T37: =IF(E37="",IF(ISNUMBER(SEARCH("NOT NULL",UPPER(E$3))),"''","null"),SUBSTITUTE(VLOOKUP(E$2,convert!$A$1:$B$4,2,0),"@@@",E37)) -> 50 | U37: =IF(F37="",IF(ISNUMBER(SEARCH("NOT NULL",UPPER(F$3))),"''","null"),SUBSTITUTE(VLOOKUP(F$2,convert!$A$1:$B$4,2,0),"@@@",F37)) -> 75 | V37: =IF(G37="",IF(ISNUMBER(SEARCH("NOT NULL",UPPER(G$3))),"''","null"),SUBSTITUTE(VLOOKUP(G$2,convert!$A$1:$B$4,2,0),"@@@",G37)) -> 60 | W37: =IF(H37="",IF(ISNUMBER(SEARCH("NOT NULL",UPPER(H$3))),"''","null"),SUBSTITUTE(VLOOKUP(H$2,convert!$A$1:$B$4,2,0),"@@@",H37)) -> 120 | ... AD37: =IF(O37="",IF(ISNUMBER(SEARCH("NOT NULL",UPPER(O$3))),"''","null"),SUBSTITUTE(VLOOKUP(O$2,convert!$A$1:$B$4,2,0),"@@@",O37)) -> FALSE | AE37: =" ("&_xlfn.TEXTJOIN(", ",FALSE,P37:AD37)&")," -> ('0025N02', 'ピカチュウ', 45, 80, 50, 75, 60, 120, '相棒', 'electric', null, 'g7pv', null, null, FALSE),
A38: 0026N01 | B38: ライチュウ | C38: 60 | D38: 90 | E38: 55 | F38: 90 | G38: 80 | H38: 110 | J38: electric | L38: g1 | O38: TRUE | P38: =IF(A38="",IF(ISNUMBER(SEARCH("NOT NULL",UPPER(A$3))),"''","null"),SUBSTITUTE(VLOOKUP(A$2,convert!$A$1:$B$4,2,0),"@@@",A38)) -> '0026N01' | Q38: =IF(B38="",IF(ISNUMBER(SEARCH("NOT NULL",UPPER(B$3))),"''","null"),SUBSTITUTE(VLOOKUP(B$2,convert!$A$1:$B$4,2,0),"@@@",B38)) -> 'ライチュウ' | R38: =IF(C38="",IF(ISNUMBER(SEARCH("NOT NULL",UPPER(C$3))),"''","null"),SUBSTITUTE(VLOOKUP(C$2,convert!$A$1:$B$4,2,0),"@@@",C38)) -> 60 | S38: =IF(D38="",IF(ISNUMBER(SEARCH("NOT NULL",UPPER(D$3))),"''","null"),SUBSTITUTE(VLOOKUP(D$2,convert!$A$1:$B$4,2,0),"@@@",D38)) -> 90 | T38: =IF(E38="",IF(ISNUMBER(SEARCH("NOT NULL",UPPER(E$3))),"''","null"),SUBSTITUTE(VLOOKUP(E$2,convert!$A$1:$B$4,2,0),"@@@",E38)) -> 55 | U38: =IF(F38="",IF(ISNUMBER(SEARCH("NOT NULL",UPPER(F$3))),"''","null"),SUBSTITUTE(VLOOKUP(F$2,convert!$A$1:$B$4,2,0),"@@@",F38)) -> 90 | V38: =IF(G38="",IF(ISNUMBER(SEARCH("NOT NULL",UPPER(G$3))),"''","null"),SUBSTITUTE(VLOOKUP(G$2,convert!$A$1:$B$4,2,0),"@@@",G38)) -> 80 | W38: =IF(H38="",IF(ISNUMBER(SEARCH("NOT NULL",UPPER(H$3))),"''","null"),SUBSTITUTE(VLOOKUP(H$2,convert!$A$1:$B$4,2,0),"@@@",H38)) -> 110 | ... AD38: =IF(O38="",IF(ISNUMBER(SEARCH("NOT NULL",UPPER(O$3))),"''","null"),SUBSTITUTE(VLOOKUP(O$2,convert!$A$1:$B$4,2,0),"@@@",O38)) -> TRUE | AE38: =" ("&_xlfn.TEXTJOIN(", ",FALSE,P38:AD38)&")," -> ('0026N01', 'ライチュウ', 60, 90, 55, 90, 80, 110, '', 'electric', null, 'g1', null, null, TRUE),
A39: 0026A01 | B39: ライチュウ | C39: 60 | D39: 85 | E39: 50 | F39: 95 | G39: 85 | H39: 110 | I39: アローラのすがた | J39: electric | K39: psychic | L39: g7 | O39: TRUE | P39: =IF(A39="",IF(ISNUMBER(SEARCH("NOT NULL",UPPER(A$3))),"''","null"),SUBSTITUTE(VLOOKUP(A$2,convert!$A$1:$B$4,2,0),"@@@",A39)) -> '0026A01' | Q39: =IF(B39="",IF(ISNUMBER(SEARCH("NOT NULL",UPPER(B$3))),"''","null"),SUBSTITUTE(VLOOKUP(B$2,convert!$A$1:$B$4,2,0),"@@@",B39)) -> 'ライチュウ' | R39: =IF(C39="",IF(ISNUMBER(SEARCH("NOT NULL",UPPER(C$3))),"''","null"),SUBSTITUTE(VLOOKUP(C$2,convert!$A$1:$B$4,2,0),"@@@",C39)) -> 60 | S39: =IF(D39="",IF(ISNUMBER(SEARCH("NOT NULL",UPPER(D$3))),"''","null"),SUBSTITUTE(VLOOKUP(D$2,convert!$A$1:$B$4,2,0),"@@@",D39)) -> 85 | T39: =IF(E39="",IF(ISNUMBER(SEARCH("NOT NULL",UPPER(E$3))),"''","null"),SUBSTITUTE(VLOOKUP(E$2,convert!$A$1:$B$4,2,0),"@@@",E39)) -> 50 | U39: =IF(F39="",IF(ISNUMBER(SEARCH("NOT NULL",UPPER(F$3))),"''","null"),SUBSTITUTE(VLOOKUP(F$2,convert!$A$1:$B$4,2,0),"@@@",F39)) -> 95 | V39: =IF(G39="",IF(ISNUMBER(SEARCH("NOT NULL",UPPER(G$3))),"''","null"),SUBSTITUTE(VLOOKUP(G$2,convert!$A$1:$B$4,2,0),"@@@",G39)) -> 85 | W39: =IF(H39="",IF(ISNUMBER(SEARCH("NOT NULL",UPPER(H$3))),"''","null"),SUBSTITUTE(VLOOKUP(H$2,convert!$A$1:$B$4,2,0),"@@@",H39)) -> 110 | ... AD39: =IF(O39="",IF(ISNUMBER(SEARCH("NOT NULL",UPPER(O$3))),"''","null"),SUBSTITUTE(VLOOKUP(O$2,convert!$A$1:$B$4,2,0),"@@@",O39)) -> TRUE | AE39: =" ("&_xlfn.TEXTJOIN(", ",FALSE,P39:AD39)&")," -> ('0026A01', 'ライチュウ', 60, 85, 50, 95, 85, 110, 'アローラのすがた', 'electric', 'psychic', 'g7', null, null, TRUE),
A40: 0027N01 | B40: サンド | C40: 50 | D40: 75 | E40: 85 | F40: 20 | G40: 30 | H40: 40 | J40: ground | L40: g1 | O40: TRUE | P40: =IF(A40="",IF(ISNUMBER(SEARCH("NOT NULL",UPPER(A$3))),"''","null"),SUBSTITUTE(VLOOKUP(A$2,convert!$A$1:$B$4,2,0),"@@@",A40)) -> '0027N01' | Q40: =IF(B40="",IF(ISNUMBER(SEARCH("NOT NULL",UPPER(B$3))),"''","null"),SUBSTITUTE(VLOOKUP(B$2,convert!$A$1:$B$4,2,0),"@@@",B40)) -> 'サンド' | R40: =IF(C40="",IF(ISNUMBER(SEARCH("NOT NULL",UPPER(C$3))),"''","null"),SUBSTITUTE(VLOOKUP(C$2,convert!$A$1:$B$4,2,0),"@@@",C40)) -> 50 | S40: =IF(D40="",IF(ISNUMBER(SEARCH("NOT NULL",UPPER(D$3))),"''","null"),SUBSTITUTE(VLOOKUP(D$2,convert!$A$1:$B$4,2,0),"@@@",D40)) -> 75 | T40: =IF(E40="",IF(ISNUMBER(SEARCH("NOT NULL",UPPER(E$3))),"''","null"),SUBSTITUTE(VLOOKUP(E$2,convert!$A$1:$B$4,2,0),"@@@",E40)) -> 85 | U40: =IF(F40="",IF(ISNUMBER(SEARCH("NOT NULL",UPPER(F$3))),"''","null"),SUBSTITUTE(VLOOKUP(F$2,convert!$A$1:$B$4,2,0),"@@@",F40)) -> 20 | V40: =IF(G40="",IF(ISNUMBER(SEARCH("NOT NULL",UPPER(G$3))),"''","null"),SUBSTITUTE(VLOOKUP(G$2,convert!$A$1:$B$4,2,0),"@@@",G40)) -> 30 | W40: =IF(H40="",IF(ISNUMBER(SEARCH("NOT NULL",UPPER(H$3))),"''","null"),SUBSTITUTE(VLOOKUP(H$2,convert!$A$1:$B$4,2,0),"@@@",H40)) -> 40 | ... AD40: =IF(O40="",IF(ISNUMBER(SEARCH("NOT NULL",UPPER(O$3))),"''","null"),SUBSTITUTE(VLOOKUP(O$2,convert!$A$1:$B$4,2,0),"@@@",O40)) -> TRUE | AE40: =" ("&_xlfn.TEXTJOIN(", ",FALSE,P40:AD40)&")," -> ('0027N01', 'サンド', 50, 75, 85, 20, 30, 40, '', 'ground', null, 'g1', null, null, TRUE),
...

Sheet convert
A1: bpchar | B1: '@@@'
A2: varchar | B2: '@@@'
A3: number | B3: @@@
A4: boolean | B4: @@@
